Workbook

Sheet 报价表
A1: 合肥鲲源贸易有限公司钢材报价单 | F1: 预备发货厂家 | O1: 钢厂 | P1: 徐钢 | R1: 闽源 | T1: 马长江 | AD1: 金虹 | AF1: 南钢 | AH1: 鄂钢 | AJ1: 贵航 | AL1: 萍钢 | AN1: 桂鑫 | AP1: 金安 | AR1: 马钢 | AT1: 中天 | AV1: 六钢 | AX1: 新兴铸管 | BP1: 马钢 | BR1: 中天 | BT1: 六钢 | BV1: 萍钢 | BZ1: 新兴铸管
O2: 高线10基价 | P2: =徐钢!H2 | Q2: =徐钢!I2 | R2: =闽源!H2 | S2: =闽源!I2 | T2: =长江!H2 | U2: =长江!I2 | V2: =长江!J2 | W2: =长江!K2 | X2: =长江!L2 | Y2: =长江!M2 | Z2: =长江!N2 | AA2: =长江!O2 | AB2: =萍钢!J2 | AC2: =萍钢!K2 | AD2: =金虹!H2 | AE2: =金虹!I2 | AF2: =南钢!H2 | AG2: =南钢!I2 | AH2: =鄂钢!H2 | AI2: =鄂钢!I2 | AJ2: =贵航!H2 | AK2: =贵航!I2 | AL2: =萍钢!H2 | AM2: =萍钢!I2 | AN2: =桂鑫!H2 | AO2: =桂鑫!I2 | AP2: =金安!G2 | AQ2: =金安!H2 | AR2: =马钢!H2 | AS2: =马钢!I2 | AT2: =中天!H2 | AU2: =中天!I2 | AV2: 0 | AW2: 0 | AX2: =新兴铸管!H2 | AY2: =新兴铸管!I2 | AZ2: =新兴铸管!J2 | BA2: =新兴铸管!K2 | BP2: =马钢!T2 | BQ2: =马钢!U2 | BR2: 0 | BS2: / | BT2: 0 | BU2: 0 | BV2: 0 | BW2: 0 | BX2: 0 | BY2: 0 | BZ2: 0 | CA2: / | CB2: 0 | CC2: /
O3: 盘螺10基价 | P3: =徐钢!H3 | Q3: =徐钢!I3 | R3: =闽源!H3 | S3: =闽源!I3 | T3: =长江!H3 | U3: =长江!I3 | V3: =长江!J3 | W3: =长江!K3 | X3: =长江!L3 | Y3: =长江!M3 | Z3: =长江!N3 | AA3: =长江!O3 | AB3: =萍钢!J3 | AC3: =萍钢!K3 | AD3: =金虹!H3 | AE3: =金虹!I3 | AF3: =南钢!H3 | AG3: =南钢!I3 | AH3: =鄂钢!H3 | AI3: =鄂钢!I3 | AJ3: =贵航!H3 | AK3: =贵航!I3 | AL3: =萍钢!H3 | AM3: =萍钢!I3 | AN3: =桂鑫!H3 | AO3: =桂鑫!I3 | AP3: =金安!G3 | AQ3: =金安!H3 | AR3: =马钢!H3 | AS3: =马钢!I3 | AT3: =中天!H3 | AU3: =中天!I3 | AV3: 0 | AW3: 0 | AX3: =新兴铸管!H3 | AY3: =新兴铸管!I3 | AZ3: =新兴铸管!J3 | BA3: =新兴铸管!K3 | BP3: =马钢!T3 | BQ3: =马钢!U3 | BR3: 0 | BS3: / | BT3: 0 | BU3: 0 | BV3: 0 | BW3: 0 | BX3: 0 | BY3: 0 | BZ3: 0 | CA3: / | CB3: 0 | CC3: /
A4: 需求单位：蚌埠市蚌投贸易有限公司（蚌埠市龙子湖区） | G4: 发货时间 | O4: 螺纹18基价 | P4: =徐钢!H4 | Q4: =徐钢!I4 | R4: =闽源!H4 | S4: =闽源!I4 | T4: =长江!H4 | U4: =长江!I4 | V4: =长江!J4 | W4: =长江!K4 | X4: =长江!L4 | Y4: =长江!M4 | Z4: =长江!N4 | AA4: =长江!O4 | AB4: =萍钢!J4 | AC4: =萍钢!K4 | AD4: =金虹!H4 | AE4: =金虹!I4 | AF4: =南钢!H4 | AG4: =南钢!I4 | AH4: =鄂钢!H4 | AI4: =鄂钢!I4 | AJ4: =贵航!H4 | AK4: =贵航!I4 | AL4: =萍钢!H4 | AM4: =萍钢!I4 | AN4: =桂鑫!H4 | AO4: =桂鑫!I4 | AP4: =金安!G4 | AQ4: =金安!H4 | AR4: =马钢!H4 | AS4: =马钢!I4 | AT4: =中天!H4 | AU4: =中天!I4 | AV4: 0 | AW4: 0 | AX4: =新兴铸管!H4 | AY4: =新兴铸管!I4 | AZ4: =新兴铸管!J4 | BA4: =新兴铸管!K4 | BP4: =马钢!T4 | BQ4: =马钢!U4 | BR4: 0 | BS4: / | BT4: 0 | BU4: 0 | BV4: 0 | BW4: 0 | BX4: 0 | BY4: 0 | BZ4: 0 | CA4: / | CB4: 0 | CC4: /
O5: 不开票运费 | P5: =徐钢!H5 | Q5: =徐钢!I5 | R5: =闽源!H5 | S5: =闽源!I5 | T5: =长江!H5 | U5: =长江!I5 | V5: =长江!J5 | W5: =长江!K5 | X5: =长江!L5 | Y5: =长江!M5 | Z5: =长江!N5 | AA5: =长江!O5 | AB5: =萍钢!K5 | AC5: =中天!H5 | AD5: =金虹!H5 | AE5: =金虹!I5 | AF5: =南钢!I5 | AH5: =鄂钢!H5 | AI5: =鄂钢!I5 | AJ5: =贵航!H5 | AK5: =贵航!I5 | AL5: =萍钢!H5 | AM5: =萍钢!I5 | AN5: =桂鑫!H5 | AO5: =桂鑫!I5 | AP5: =金安!G5 | AQ5: =金安!H5 | AR5: =马钢!H5 | AS5: =马钢!I5 | AT5: =中天!I5 | AU5: =新兴铸管!H5 | AV5: 0 | AW5: 0 | AX5: =新兴铸管!I5 | AY5: =新兴铸管!J5 | AZ5: =新兴铸管!K5 | BA5: =南钢!H5 | BP5: =马钢!T5 | BQ5: =马钢!U5 | BR5: / | BS5: 0 | BT5: 0 | BU5: 0 | BV5: 0 | BW5: 0 | BX5: / | BY5: 0 | BZ5: / | CA5: 0 | CB5: / | CC5: 0
G6: 提货单位 | H6: 长江 | I6: 南钢 | J6: 贵航 | K6: 贵航 | L6: 闽源 | M6: 徐纲 | N6: 萍钢 | O6: 一票制运费 | P6: =徐钢!H6 | Q6: =徐钢!I6 | R6: =闽源!H6 | S6: =闽源!I6 | T6: =长江!H6 | U6: =长江!I6 | V6: =长江!J6 | W6: =长江!K6 | X6: =长江!L6 | Y6: =长江!M6 | Z6: =长江!N6 | AA6: =长江!O6 | AB6: =萍钢!J6 | AC6: =萍钢!K6 | AD6: =金虹!H6 | AE6: =金虹!I6 | AF6: =南钢!H6 | AG6: =南钢!I6 | AH6: =鄂钢!H6 | AI6: =鄂钢!I6 | AJ6: =贵航!H6 | AK6: =贵航!I6 | AL6: =萍钢!H6 | AM6: =萍钢!I6 | AN6: =桂鑫!H6 | AO6: =桂鑫!I6 | AP6: =金安!G6 | AQ6: =金安!H6 | AR6: =马钢!H6 | AS6: =马钢!I6 | AT6: =中天!H6 | AU6: =中天!I6 | AV6: 0 | AW6: / | AX6: =新兴铸管!H6 | AY6: =新兴铸管!I6 | AZ6: =新兴铸管!J6 | BA6: =新兴铸管!K6 | BP6: =马钢!T6 | BQ6: =马钢!U6 | BR6: 120 | BS6: 0 | BT6: 0 | BU6: / | BV6: 60 | BW6: 0 | BX6: 120 | BY6: / | BZ6: 160 | CA6: 0 | CB6: 0 | CC6: /
H7: 蚌埠库 | I7: 厂发 | J7: 厂发 | K7: 厂发 | L7: 厂发 | M7: 厂发 | O7: 附加运费 | P7: =徐钢!H7 | Q7: =徐钢!I7 | R7: =闽源!H7 | S7: =闽源!I7 | T7: =长江!H7 | U7: =长江!I7 | V7: =长江!J7 | W7: =长江!K7 | X7: =长江!L7 | Y7: =长江!M7 | Z7: =长江!N7 | AA7: =长江!O7 | AB7: =萍钢!J7 | AC7: =萍钢!K7 | AD7: =金虹!H7 | AE7: =金虹!I7 | AF7: =南钢!H7 | AG7: =南钢!I7 | AH7: =鄂钢!H7 | AI7: =鄂钢!I7 | AJ7: =贵航!H7 | AK7: =贵航!I7 | AL7: =萍钢!H7 | AM7: =萍钢!I7 | AN7: =桂鑫!H7 | AO7: =桂鑫!I7 | AP7: =金安!G7 | AR7: =马钢!H7 | AS7: =马钢!I7 | AT7: =中天!H7 | AU7: =中天!I7 | AV7: 0 | AW7: / | AX7: =新兴铸管!H7 | AY7: =新兴铸管!I7 | AZ7: =新兴铸管!J7 | BA7: =新兴铸管!K7 | BP7: =马钢!T7 | BQ7: =马钢!U7 | BR7: 0 | BS7: / | BT7: 0 | BU7: / | BV7: 0 | BW7: 0 | BX7: 0 | BY7: / | BZ7: 0 | CA7: / | CB7: 0 | CC7: /
A8: 等级 | B8: 规格 | C8: 长度（米） | D8: 材质 | E8: 数量 | F8: 金额 | G8: 提货网差 | H8: 数量（吨） | I8: 数量（吨） | J8: 数量（吨） | K8: 数量（吨） | M8: 数量（吨） | P8: =徐钢!H8 | Q8: =徐钢!I8 | R8: =闽源!H8 | S8: =闽源!I8 | T8: =长江!H8 | U8: =长江!I8 | V8: =长江!J8 | W8: =长江!K8 | X8: =长江!L8 | Y8: =长江!M8 | Z8: =长江!N8 | AA8: =长江!O8 | AB8: =萍钢!J8 | AC8: =萍钢!K8 | AD8: =金虹!H8 | AE8: =金虹!I8 | AF8: =南钢!H8 | AG8: =南钢!I8 | AH8: =鄂钢!H8 | AI8: =鄂钢!I8 | AJ8: =贵航!H8 | AK8: =贵航!I8 | AL8: =萍钢!H8 | AM8: =萍钢!I8 | AN8: =桂鑫!H8 | AO8: =桂鑫!I8 | AP8: =金安!G8 | AQ8: =金安!H8 | AR8: =马钢!H8 | AS8: =马钢!I8 | AT8: =中天!H8 | AU8: =中天!I8 | AV8: 闽曜 | AW8: 网差 | AX8: =新兴铸管!H8 | AY8: =新兴铸管!I8 | AZ8: =新兴铸管!J8 | BA8: =新兴铸管!K8 | BP8: =马钢!T8 | BQ8: =马钢!U8 | BR8: 筑建 | BS8: 网差 | BT8: 闽曜 | BU8: 网差 | BV8: 嘉倍 | BW8: 网差 | BX8: 骞腾 | BY8: 网差 | BZ8: 爱军 | CA8: 网差 | CB8: 芜湖鑫盛 | CC8: 网差
A9: 一级钢 | B9: 6 | D9: HPB300 | F9: =E9*G9 | P9: =徐钢!H9 | Q9: =徐钢!I9 | R9: =闽源!H9 | S9: =闽源!I9 | T9: =长江!H9 | U9: =长江!I9 | V9: =长江!J9 | W9: =长江!K9 | X9: =长江!L9 | Y9: =长江!M9 | Z9: =长江!N9 | AA9: =长江!O9 | AB9: =萍钢!J9 | AC9: =萍钢!K9 | AD9: =金虹!H9 | AE9: =金虹!I9 | AF9: =南钢!H9 | AG9: =南钢!I9 | AH9: =鄂钢!H9 | AI9: =鄂钢!I9 | AJ9: =贵航!H9 | AK9: =贵航!I9 | AL9: =萍钢!H9 | AM9: =萍钢!I9 | AN9: =桂鑫!H9 | AO9: =桂鑫!I9 | AP9: =金安!G9 | AQ9: =金安!H9 | AR9: =马钢!H9 | AS9: =马钢!I9 | AT9: =中天!H9 | AU9: =中天!I9 | AV9: 100 | AW9: 0 | AX9: =新兴铸管!H9 | AY9: =新兴铸管!I9 | AZ9: =新兴铸管!J9 | BA9: =新兴铸管!K9 | BP9: =马钢!T9 | BQ9: =马钢!U9 | BR9: / | BS9: / | BT9: 100 | BU9: 0 | BV9: / | BW9: 0 | BX9: / | BY9: / | BZ9: / | CA9: / | CB9: / | CC9: /
B10: 8 | D10: HPB300 | F10: =E10*G10 | P10: =徐钢!H10 | Q10: =徐钢!I10 | R10: =闽源!H10 | S10: =闽源!I10 | T10: =长江!H10 | U10: =长江!I10 | V10: =长江!J10 | W10: =长江!K10 | X10: =长江!L10 | Y10: =长江!M10 | Z10: =长江!N10 | AA10: =长江!O10 | AB10: =萍钢!J10 | AC10: =萍钢!K10 | AD10: =金虹!H10 | AE10: =金虹!I10 | AF10: =南钢!H10 | AG10: =南钢!I10 | AH10: =鄂钢!H10 | AI10: =鄂钢!I10 | AJ10: =贵航!H10 | AK10: =贵航!I10 | AL10: =萍钢!H10 | AM10: =萍钢!I10 | AN10: =桂鑫!H10 | AO10: =桂鑫!I10 | AP10: =金安!G10 | AQ10: =金安!H10 | AR10: =马钢!H10 | AS10: =马钢!I10 | AT10: =中天!H10 | AU10: =中天!I10 | AV10: 0 | AW10: 0 | AX10: =新兴铸管!H10 | AY10: =新兴铸管!I10 | AZ10: =新兴铸管!J10 | BA10: =新兴铸管!K10 | BP10: =马钢!T10 | BQ10: =马钢!U10 | BR10: / | BS10: / | BT10: 0 | BU10: 0 | BV10: / | BW10: 0 | BX10: / | BY10: / | BZ10: / | CA10: / | CB10: / | CC10: /
B11: 10 | D11: HPB300 | F11: =E11*G11 | P11: =徐钢!H11 | Q11: =徐钢!I11 | R11: =闽源!H11 | S11: =闽源!I11 | T11: =长江!H11 | U11: =长江!I11 | V11: =长江!J11 | W11: =长江!K11 | X11: =长江!L11 | Y11: =长江!M11 | Z11: =长江!N11 | AA11: =长江!O11 | AB11: =萍钢!J11 | AC11: =萍钢!K11 | AD11: =金虹!H11 | AE11: =金虹!I11 | AF11: =南钢!H11 | AG11: =南钢!I11 | AH11: =鄂钢!H11 | AI11: =鄂钢!I11 | AJ11: =贵航!H11 | AK11: =贵航!I11 | AL11: =萍钢!H11 | AM11: =萍钢!I11 | AN11: =桂鑫!H11 | AO11: =桂鑫!I11 | AP11: =金安!G11 | AQ11: =金安!H11 | AR11: =马钢!H11 | AS11: =马钢!I11 | AT11: =中天!H11 | AU11: =中天!I11 | AV11: 0 | AW11: 0 | AX11: =新兴铸管!H11 | AY11: =新兴铸管!I11 | AZ11: =新兴铸管!J11 | BA11: =新兴铸管!K11 | BP11: =马钢!T11 | BQ11: =马钢!U11 | BR11: / | BS11: / | BT11: 0 | BU11: 0 | BV11: / | BX11: / | BY11: / | BZ11: / | CA11: / | CB11: / | CC11: /
A12: 抗震 三级钢 | B12: 6 | D12: HRB400E | E12: 12 | F12: =E12*G12 | P12: =徐钢!H12 | Q12: =徐钢!I12 | R12: =闽源!H12 | S12: =闽源!I12 | T12: =长江!H12 | U12: =长江!I12 | V12: =长江!J12 | W12: =长江!K12 | X12: =长江!L12 | Y12: =长江!M12 | Z12: =长江!N12 | AA12: =长江!O12 | AB12: =萍钢!J12 | AC12: =萍钢!K12 | AD12: =金虹!H12 | AE12: =金虹!I12 | AF12: =南钢!H12 | AG12: =南钢!I12 | AH12: =鄂钢!H12 | AI12: =鄂钢!I12 | AJ12: =贵航!H12 | AK12: =贵航!I12 | AL12: =萍钢!H12 | AM12: =萍钢!I12 | AN12: =桂鑫!H12 | AO12: =桂鑫!I12 | AP12: =金安!G12 | AQ12: =金安!H12 | AR12: =马钢!H12 | AS12: =马钢!I12 | AT12: =中天!H12 | AU12: =中天!I12 | AV12: 360 | AW12: 3520 | AX12: =新兴铸管!H12 | AY12: =新兴铸管!I12 | AZ12: =新兴铸管!J12 | BA12: =新兴铸管!K12 | BP12: =马钢!T12 | BQ12: =马钢!U12 | BR12: 420 | BS12: -120 | BT12: 360 | BU12: 3520 | BV12: 360 | BW12: -60 | BX12: 470 | BY12: -170 | BZ12: 300 | CA12: #VALUE! | CB12: 200 | CC12: #VALUE!
B13: 8 | D13: HRB400E | E13: 44 | F13: =E13*G13 | P13: =徐钢!H13 | Q13: =徐钢!I13 | R13: =闽源!H13 | S13: =闽源!I13 | T13: =长江!H13 | U13: =长江!I13 | V13: =长江!J13 | W13: =长江!K13 | X13: =长江!L13 | Y13: =长江!M13 | Z13: =长江!N13 | AA13: =长江!O13 | AB13: =萍钢!J13 | AC13: =萍钢!K13 | AD13: =金虹!H13 | AE13: =金虹!I13 | AF13: =南钢!H13 | AG13: =南钢!I13 | AH13: =鄂钢!H13 | AI13: =鄂钢!I13 | AJ13: =贵航!H13 | AK13: =贵航!I13 | AL13: =萍钢!H13 | AM13: =萍钢!I13 | AN13: =桂鑫!H13 | AO13: =桂鑫!I13 | AP13: =金安!G13 | AQ13: =金安!H13 | AR13: =马钢!H13 | AS13: =马钢!I13 | AT13: =中天!H13 | AU13: =中天!I13 | AV13: 0 | AW13: 3520 | AX13: =新兴铸管!H13 | AY13: =新兴铸管!I13 | AZ13: =新兴铸管!J13 | BA13: =新兴铸管!K13 | BP13: =马钢!T13 | BQ13: =马钢!U13 | BR13: 120 | BS13: -120 | BT13: 0 | BU13: 3520 | BV13: 60 | BW13: -60 | BX13: 120 | BY13: -120 | BZ13: 160 | CA13: -160 | CB13: 0 | CC13: 0
B14: 10 | D14: HRB400E | E14: 12 | F14: =E14*G14 | P14: =徐钢!H14 | Q14: =徐钢!I14 | R14: =闽源!H14 | S14: =闽源!I14 | T14: =长江!H14 | U14: =长江!I14 | V14: =长江!J14 | W14: =长江!K14 | X14: =长江!L14 | Y14: =长江!M14 | Z14: =长江!N14 | AA14: =长江!O14 | AB14: =萍钢!J14 | AC14: =萍钢!K14 | AD14: =金虹!H14 | AE14: =金虹!I14 | AF14: =南钢!H14 | AG14: =南钢!I14 | AH14: =鄂钢!H14 | AI14: =鄂钢!I14 | AJ14: =贵航!H14 | AK14: =贵航!I14 | AL14: =萍钢!H14 | AM14: =萍钢!I14 | AN14: =桂鑫!H14 | AO14: =桂鑫!I14 | AP14: =金安!G14 | AQ14: =金安!H14 | AR14: =马钢!H14 | AS14: =马钢!I14 | AT14: =中天!H14 | AU14: =中天!I14 | AV14: 0 | AW14: 3520 | AX14: =新兴铸管!H14 | AY14: =新兴铸管!I14 | AZ14: =新兴铸管!J14 | BA14: =新兴铸管!K14 | BP14: =马钢!T14 | BQ14: =马钢!U14 | BR14: 120 | BS14: -120 | BT14: 0 | BU14: 3520 | BV14: 60 | BW14: -60 | BX14: 120 | BY14: -120 | BZ14: 160 | CA14: -160 | CB14: 0 | CC14: 0
B15: 10 | C15: 9 | D15: HRB400E | F15: =E15*G15 | P15: =徐钢!H15 | Q15: =徐钢!I15 | R15: =闽源!H15 | S15: =闽源!I15 | T15: =长江!H15 | U15: =长江!I15 | V15: =长江!J15 | W15: =长江!K15 | X15: =长江!L15 | Y15: =长江!M15 | Z15: =长江!N15 | AA15: =长江!O15 | AB15: =萍钢!J15 | AC15: =萍钢!K15 | AD15: =#REF! | AE15: =金虹!I15 | AF15: =南钢!H15 | AG15: =南钢!I15 | AH15: =鄂钢!H15 | AI15: =鄂钢!I15 | AJ15: =贵航!H15 | AK15: =贵航!I15 | AL15: =萍钢!H15 | AM15: =萍钢!I15 | AN15: =桂鑫!H15 | AO15: =桂鑫!I15 | AP15: =金安!G15 | AQ15: =金安!H15 | AR15: =马钢!H15 | AS15: =马钢!I15 | AT15: =中天!H15 | AU15: =中天!I15 | AV15: 0 | AW15: 0 | AX15: =新兴铸管!H15 | AY15: =新兴铸管!I15 | AZ15: =新兴铸管!J15 | BA15: =新兴铸管!K15 | BP15: =马钢!T15 | BQ15: =马钢!U15 | BR15: 0 | BS15: 0 | BT15: 0 | BU15: 0 | BV15: 0 | BW15: 0 | BX15: 0 | BY15: #VALUE! | BZ15: 0 | CA15: 0 | CB15: 0 | CC15: 0
B16: 12 | C16: 9 | D16: HRB400E | E16: 20 | F16: =E16*G16 | P16: =徐钢!H16 | Q16: =徐钢!I16 | R16: =闽源!H16 | S16: =闽源!I16 | T16: =长江!H16 | U16: =长江!I16 | V16: =长江!J16 | W16: =长江!K16 | X16: =长江!L16 | Y16: =长江!M16 | Z16: =长江!N16 | AA16: =长江!O16 | AB16: =萍钢!J16 | AC16: =萍钢!K16 | AD16: =金虹!H16 | AE16: =金虹!I16 | AF16: =南钢!H16 | AG16: =南钢!I16 | AH16: =鄂钢!H16 | AI16: =鄂钢!I16 | AJ16: =贵航!H16 | AK16: =贵航!I16 | AL16: =萍钢!H16 | AM16: =萍钢!I16 | AN16: =桂鑫!H16 | AO16: =桂鑫!I16 | AP16: =金安!G16 | AQ16: =金安!H16 | AR16: =马钢!H16 | AS16: =马钢!I16 | AT16: =中天!H16 | AU16: =中天!I16 | AV16: 90 | AW16: 3410 | AX16: =新兴铸管!H16 | AY16: =新兴铸管!I16 | AZ16: =新兴铸管!J16 | BA16: =新兴铸管!K16 | BP16: =马钢!T16 | BQ16: =马钢!U16 | BR16: 220 | BS16: -140 | BT16: 90 | BU16: 3410 | BV16: 130 | BW16: -50 | BX16: 260 | BY16: -180 | BZ16: 290 | CA16: -290 | CB16: 100 | CC16: -100
B17: 12 | C17: 12 | D17: HRB400E | F17: =E17*G17 | P17: =徐钢!H17 | Q17: =徐钢!I17 | R17: =闽源!H17 | S17: =闽源!I17 | T17: =长江!H17 | U17: =长江!I17 | V17: =长江!J17 | W17: =长江!K17 | X17: =长江!L17 | Y17: =长江!M17 | Z17: =长江!N17 | AA17: =长江!O17 | AB17: =萍钢!J17 | AC17: =萍钢!K17 | AD17: =金虹!H17 | AE17: =金虹!I17 | AF17: =南钢!H17 | AG17: =南钢!I17 | AH17: =鄂钢!H17 | AI17: =鄂钢!I17 | AJ17: =贵航!H17 | AK17: =贵航!I17 | AL17: =萍钢!H17 | AM17: =萍钢!I17 | AN17: =桂鑫!H17 | AO17: =桂鑫!I17 | AP17: =金安!G17 | AQ17: =金安!H17 | AR17: =马钢!H17 | AS17: =马钢!I17 | AT17: =中天!H17 | AU17: =中天!I17 | AV17: 90 | AW17: 3410 | AX17: =新兴铸管!H17 | AY17: =新兴铸管!I17 | AZ17: =新兴铸管!J17 | BA17: =新兴铸管!K17 | BP17: =马钢!T17 | BQ17: =马钢!U17 | BR17: 220 | BS17: -140 | BT17: 90 | BU17: 3410 | BV17: 130 | BW17: -50 | BX17: 310 | BY17: -230 | BZ17: 290 | CA17: -290 | CB17: 100 | CC17: -100
B18: 14 | C18: 9 | D18: HRB400E | F18: =E18*G18 | P18: =徐钢!H18 | Q18: =徐钢!I18 | R18: =闽源!H18 | S18: =闽源!I18 | T18: =长江!H18 | U18: =长江!I18 | V18: =长江!J18 | W18: =长江!K18 | X18: =长江!L18 | Y18: =长江!M18 | Z18: =长江!N18 | AA18: =长江!O18 | AB18: =萍钢!J18 | AC18: =萍钢!K18 | AD18: =金虹!H18 | AE18: =金虹!I18 | AF18: =南钢!H18 | AG18: =南钢!I18 | AH18: =鄂钢!H18 | AI18: =鄂钢!I18 | AJ18: =贵航!H18 | AK18: =贵航!I18 | AL18: =萍钢!H18 | AM18: =萍钢!I18 | AN18: =桂鑫!H18 | AO18: =桂鑫!I18 | AP18: =金安!G18 | AQ18: =金安!H18 | AR18: =马钢!H18 | AS18: =马钢!I18 | AT18: =中天!H18 | AU18: =中天!I18 | AV18: 30 | AW18: 3390 | AX18: =新兴铸管!H18 | AY18: =新兴铸管!I18 | AZ18: =新兴铸管!J18 | BA18: =新兴铸管!K18 | BP18: =马钢!T18 | BQ18: =马钢!U18 | BR18: 150 | BS18: -120 | BT18: 30 | BU18: 3390 | BV18: 90 | BW18: -60 | BX18: 220 | BY18: -190 | BZ18: 260 | CA18: -260 | CB18: 40 | CC18: -40
B19: 14 | C19: 12 | D19: HRB400E | F19: =E19*G19 | P19: =徐钢!H19 | Q19: =徐钢!I19 | R19: =闽源!H19 | S19: =闽源!I19 | T19: =长江!H19 | U19: =长江!I19 | V19: =长江!J19 | W19: =长江!K19 | X19: =长江!L19 | Y19: =长江!M19 | Z19: =长江!N19 | AA19: =长江!O19 | AB19: =萍钢!J19 | AC19: =萍钢!K19 | AD19: =金虹!H19 | AE19: =金虹!I19 | AF19: =南钢!H19 | AG19: =南钢!I19 | AH19: =鄂钢!H19 | AI19: =鄂钢!I19 | AJ19: =贵航!H19 | AK19: =贵航!I19 | AL19: =萍钢!H19 | AM19: =萍钢!I19 | AN19: =桂鑫!H19 | AO19: =桂鑫!I19 | AP19: =金安!G19 | AQ19: =金安!H19 | AR19: =马钢!H19 | AS19: =马钢!I19 | AT19: =中天!H19 | AU19: =中天!I19 | AV19: 30 | AW19: 3390 | AX19: =新兴铸管!H19 | AY19: =新兴铸管!I19 | AZ19: =新兴铸管!J19 | BA19: =新兴铸管!K19 | BP19: =马钢!T19 | BQ19: =马钢!U19 | BR19: 150 | BS19: -120 | BT19: 30 | BU19: 3390 | BV19: 90 | BW19: -60 | BX19: 270 | BY19: -240 | BZ19: 260 | CA19: -260 | CB19: 40 | CC19: -40
B20: 16 | C20: 9 | D20: HRB400E | F20: =E20*G20 | P20: =徐钢!H20 | Q20: =徐钢!I20 | R20: =闽源!H20 | S20: =闽源!I20 | T20: =长江!H20 | U20: =长江!I20 | V20: =长江!J20 | W20: =长江!K20 | X20: =长江!L20 | Y20: =长江!M20 | Z20: =长江!N20 | AA20: =长江!O20 | AB20: =萍钢!J20 | AC20: =萍钢!K20 | AD20: =金虹!H20 | AE20: =金虹!I20 | AF20: =南钢!H20 | AG20: =南钢!I20 | AH20: =鄂钢!H20 | AI20: =鄂钢!I20 | AJ20: =贵航!H20 | AK20: =贵航!I20 | AL20: =萍钢!H20 | AM20: =萍钢!I20 | AN20: =桂鑫!H20 | AO20: =桂鑫!I20 | AP20: =金安!G20 | AQ20: =金安!H20 | AR20: =马钢!H20 | AS20: =马钢!I20 | AT20: =中天!H20 | AU20: =中天!I20 | AV20: 30 | AW20: 3380 | AX20: =新兴铸管!H20 | AY20: =新兴铸管!I20 | AZ20: =新兴铸管!J20 | BA20: =新兴铸管!K20 | BP20: =马钢!T20 | BQ20: =马钢!U20 | BR20: 150 | BS20: -150 | BT20: 30 | BU20: 3380 | BV20: 90 | BW20: -60 | BX20: 220 | BY20: -190 | BZ20: 240 | CA20: -220 | CB20: 0 | CC20: 20
B21: 16 | C21: 12 | D21: HRB400E | F21: =E21*G21 | P21: =徐钢!H21 | Q21: =徐钢!I21 | R21: =闽源!H21 | S21: =闽源!I21 | T21: =长江!H21 | U21: =长江!I21 | V21: =长江!J21 | W21: =长江!K21 | X21: =长江!L21 | Y21: =长江!M21 | Z21: =长江!N21 | AA21: =长江!O21 | AB21: =萍钢!J21 | AC21: =萍钢!K21 | AD21: =金虹!H21 | AE21: =金虹!I21 | AF21: =南钢!H21 | AG21: =南钢!I21 | AH21: =鄂钢!H21 | AI21: =鄂钢!I21 | AJ21: =贵航!H21 | AK21: =贵航!I21 | AL21: =萍钢!H21 | AM21: =萍钢!I21 | AN21: =桂鑫!H21 | AO21: =桂鑫!I21 | AP21: =金安!G21 | AQ21: =金安!H21 | AR21: =马钢!H21 | AS21: =马钢!I21 | AT21: =中天!H21 | AU21: =中天!I21 | AV21: 30 | AW21: 3380 | AX21: =新兴铸管!H21 | AY21: =新兴铸管!I21 | AZ21: =新兴铸管!J21 | BA21: =新兴铸管!K21 | BP21: =马钢!T21 | BQ21: =马钢!U21 | BR21: 150 | BS21: -150 | BT21: 30 | BU21: 3380 | BV21: 90 | BW21: -60 | BX21: 270 | BY21: -240 | BZ21: 240 | CA21: -220 | CB21: 0 | CC21: 20
B22: 18 | C22: 9 | D22: HRB400E | F22: =E22*G22 | P22: =徐钢!H22 | Q22: =徐钢!I22 | R22: =闽源!H22 | S22: =闽源!I22 | T22: =长江!H22 | U22: =长江!I22 | V22: =长江!J22 | W22: =长江!K22 | X22: =长江!L22 | Y22: =长江!M22 | Z22: =长江!N22 | AA22: =长江!O22 | AB22: =萍钢!J22 | AC22: =萍钢!K22 | AD22: =金虹!H22 | AE22: =金虹!I22 | AF22: =南钢!H22 | AG22: =南钢!I22 | AH22: =鄂钢!H22 | AI22: =鄂钢!I22 | AJ22: =贵航!H22 | AK22: =贵航!I22 | AL22: =萍钢!H22 | AM22: =萍钢!I22 | AN22: =桂鑫!H22 | AO22: =桂鑫!I22 | AP22: =金安!G22 | AQ22: =金安!H22 | AR22: =马钢!H22 | AS22: =马钢!I22 | AT22: =中天!H22 | AU22: =中天!I22 | AV22: 0 | AW22: 3360 | AX22: =新兴铸管!H22 | AY22: =新兴铸管!I22 | AZ22: =新兴铸管!J22 | BA22: =新兴铸管!K22 | BP22: =马钢!T22 | BQ22: =马钢!U22 | BR22: 120 | BS22: -120 | BT22: 0 | BU22: 3360 | BV22: 90 | BW22: -90 | BX22: 230 | BY22: -230 | BZ22: 160 | CA22: -160 | CB22: 0 | CC22: 0
B23: 18 | C23: 12 | D23: HRB400E | F23: =E23*G23 | P23: =徐钢!H23 | Q23: =徐钢!I23 | R23: =闽源!H23 | S23: =闽源!I23 | T23: =长江!H23 | U23: =长江!I23 | V23: =长江!J23 | W23: =长江!K23 | X23: =长江!L23 | Y23: =长江!M23 | Z23: =长江!N23 | AA23: =长江!O23 | AB23: =萍钢!J23 | AC23: =萍钢!K23 | AD23: =金虹!H23 | AE23: =金虹!I23 | AF23: =南钢!H23 | AG23: =南钢!I23 | AH23: =鄂钢!H23 | AI23: =鄂钢!I23 | AJ23: =贵航!H23 | AK23: =贵航!I23 | AL23: =萍钢!H23 | AM23: =萍钢!I23 | AN23: =桂鑫!H23 | AO23: =桂鑫!I23 | AP23: =金安!G23 | AQ23: =金安!H23 | AR23: =马钢!H23 | AS23: =马钢!I23 | AT23: =中天!H23 | AU23: =中天!I23 | AV23: 0 | AW23: 3360 | AX23: =新兴铸管!H23 | AY23: =新兴铸管!I23 | AZ23: =新兴铸管!J23 | BA23: =新兴铸管!K23 | BP23: =马钢!T23 | BQ23: =马钢!U23 | BR23: 120 | BS23: -120 | BT23: 0 | BU23: 3360 | BV23: 90 | BW23: -90 | BX23: 280 | BY23: -280 | BZ23: 160 | CA23: -160 | CB23: 0 | CC23: 0
B24: 20 | C24: 9 | D24: HRB400E | E24: 14 | F24: =E24*G24 | P24: =徐钢!H24 | Q24: =徐钢!I24 | R24: =闽源!H24 | S24: =闽源!I24 | T24: =长江!H24 | U24: =长江!I24 | V24: =长江!J24 | W24: =长江!K24 | X24: =长江!L24 | Y24: =长江!M24 | Z24: =长江!N24 | AA24: =长江!O24 | AB24: =萍钢!J24 | AC24: =萍钢!K24 | AD24: =金虹!H24 | AE24: =金虹!I24 | AF24: =南钢!H24 | AG24: =南钢!I24 | AH24: =鄂钢!H24 | AI24: =鄂钢!I24 | AJ24: =贵航!H24 | AK24: =贵航!I24 | AL24: =萍钢!H24 | AM24: =萍钢!I24 | AN24: =桂鑫!H24 | AO24: =桂鑫!I24 | AP24: =金安!G24 | AQ24: =金安!H24 | AR24: =马钢!H24 | AS24: =马钢!I24 | AT24: =中天!H24 | AU24: =中天!I24 | AV24: 50 | AW24: 3360 | AX24: =新兴铸管!H24 | AY24: =新兴铸管!I24 | AZ24: =新兴铸管!J24 | BA24: =新兴铸管!K24 | BP24: =马钢!T24 | BQ24: =马钢!U24 | BR24: 150 | BS24: -140 | BT24: 50 | BU24: 3360 | BV24: 110 | BW24: -60 | BX24: 280 | BY24: -230 | BZ24: 180 | CA24: -130 | CB24: 0 | CC24: 50
B25: 20 | C25: 12 | D25: HRB400E | F25: =E25*G25 | P25: =徐钢!H25 | Q25: =徐钢!I25 | R25: =闽源!H25 | S25: =闽源!I25 | T25: =长江!H25 | U25: =长江!I25 | V25: =长江!J25 | W25: =长江!K25 | X25: =长江!L25 | Y25: =长江!M25 | Z25: =长江!N25 | AA25: =长江!O25 | AB25: =萍钢!J25 | AC25: =萍钢!K25 | AD25: =金虹!H25 | AE25: =金虹!I25 | AF25: =南钢!H25 | AG25: =南钢!I25 | AH25: =鄂钢!H25 | AI25: =鄂钢!I25 | AJ25: =贵航!H25 | AK25: =贵航!I25 | AL25: =萍钢!H25 | AM25: =萍钢!I25 | AN25: =桂鑫!H25 | AO25: =桂鑫!I25 | AP25: =金安!G25 | AQ25: =金安!H25 | AR25: =马钢!H25 | AS25: =马钢!I25 | AT25: =中天!H25 | AU25: =中天!I25 | AV25: 50 | AW25: 3360 | AX25: =新兴铸管!H25 | AY25: =新兴铸管!I25 | AZ25: =新兴铸管!J25 | BA25: =新兴铸管!K25 | BP25: =马钢!T25 | BQ25: =马钢!U25 | BR25: 150 | BS25: -140 | BT25: 50 | BU25: 3360 | BV25: 110 | BW25: -60 | BX25: 330 | BY25: -280 | BZ25: 180 | CA25: -130 | CB25: 0 | CC25: 50
B26: 22 | C26: 9 | D26: HRB400E | F26: =E26*G26 | P26: =徐钢!H26 | Q26: =徐钢!I26 | R26: =闽源!H26 | S26: =闽源!I26 | T26: =长江!H26 | U26: =长江!I26 | V26: =长江!J26 | W26: =长江!K26 | X26: =长江!L26 | Y26: =长江!M26 | Z26: =长江!N26 | AA26: =长江!O26 | AB26: =萍钢!J26 | AC26: =萍钢!K26 | AD26: =金虹!H26 | AE26: =金虹!I26 | AF26: =南钢!H26 | AG26: =南钢!I26 | AH26: =鄂钢!H26 | AI26: =鄂钢!I26 | AJ26: =贵航!H26 | AK26: =贵航!I26 | AL26: =萍钢!H26 | AM26: =萍钢!I26 | AN26: =桂鑫!H26 | AO26: =桂鑫!I26 | AP26: =金安!G26 | AQ26: =金安!H26 | AR26: =马钢!H26 | AS26: =马钢!I26 | AT26: =中天!H26 | AU26: =中天!I26 | AV26: 50 | AW26: 3360 | AX26: =新兴铸管!H26 | AY26: =新兴铸管!I26 | AZ26: =新兴铸管!J26 | BA26: =新兴铸管!K26 | BP26: =马钢!T26 | BQ26: =马钢!U26 | BR26: 150 | BS26: -120 | BT26: 50 | BU26: 3360 | BV26: 110 | BW26: -60 | BX26: 220 | BY26: -170 | BZ26: 180 | CA26: -130 | CB26: 0 | CC26: 50
B27: 22 | C27: 12 | D27: HRB400E | F27: =E27*G27 | P27: =徐钢!H27 | Q27: =徐钢!I27 | R27: =闽源!H27 | S27: =闽源!I27 | T27: =长江!H27 | U27: =长江!I27 | V27: =长江!J27 | W27: =长江!K27 | X27: =长江!L27 | Y27: =长江!M27 | Z27: =长江!N27 | AA27: =长江!O27 | AB27: =萍钢!J27 | AC27: =萍钢!K27 | AD27: =金虹!H27 | AE27: =金虹!I27 | AF27: =南钢!H27 | AG27: =南钢!I27 | AH27: =鄂钢!H27 | AI27: =鄂钢!I27 | AJ27: =贵航!H27 | AK27: =贵航!I27 | AL27: =萍钢!H27 | AM27: =萍钢!I27 | AN27: =桂鑫!H27 | AO27: =桂鑫!I27 | AP27: =金安!G27 | AQ27: =金安!H27 | AR27: =马钢!H27 | AS27: =马钢!I27 | AT27: =中天!H27 | AU27: =中天!I27 | AV27: 50 | AW27: 3360 | AX27: =新兴铸管!H27 | AY27: =新兴铸管!I27 | AZ27: =新兴铸管!J27 | BA27: =新兴铸管!K27 | BP27: =马钢!T27 | BQ27: =马钢!U27 | BR27: 150 | BS27: -120 | BT27: 50 | BU27: 3360 | BV27: 110 | BW27: -60 | BX27: 270 | BY27: -220 | BZ27: 180 | CA27: -130 | CB27: 0 | CC27: 50
B28: 25 | C28: 9 | D28: HRB400E | F28: =E28*G28 | P28: =徐钢!H28 | Q28: =徐钢!I28 | R28: =闽源!H28 | S28: =闽源!I28 | T28: =长江!H28 | U28: =长江!I28 | V28: =长江!J28 | W28: =长江!K28 | X28: =长江!L28 | Y28: =长江!M28 | Z28: =长江!N28 | AA28: =长江!O28 | AB28: =萍钢!J28 | AC28: =萍钢!K28 | AD28: =金虹!H28 | AE28: =金虹!I28 | AF28: =南钢!H28 | AG28: =南钢!I28 | AH28: =鄂钢!H28 | AI28: =鄂钢!I28 | AJ28: =贵航!H28 | AK28: =贵航!I28 | AL28: =萍钢!H28 | AM28: =萍钢!I28 | AN28: =桂鑫!H28 | AO28: =桂鑫!I28 | AP28: =金安!G28 | AQ28: =金安!H28 | AR28: =马钢!H28 | AS28: =马钢!I28 | AT28: =中天!H28 | AU28: =中天!I28 | AV28: 80 | AW28: 3360 | AX28: =新兴铸管!H28 | AY28: =新兴铸管!I28 | AZ28: =新兴铸管!J28 | BA28: =新兴铸管!K28 | BP28: =马钢!T28 | BQ28: =马钢!U28 | BR28: 170 | BS28: -140 | BT28: 80 | BU28: 3360 | BV28: 120 | BW28: -40 | BX28: 240 | BY28: -160 | BZ28: 220 | CA28: -150 | CB28: 0 | CC28: 70
B29: 25 | C29: 12 | D29: HRB400E | F29: =E29*G29 | P29: =徐钢!H29 | Q29: =徐钢!I29 | R29: =闽源!H29 | S29: =闽源!I29 | T29: =长江!H29 | U29: =长江!I29 | V29: =长江!J29 | W29: =长江!K29 | X29: =长江!L29 | Y29: =长江!M29 | Z29: =长江!N29 | AA29: =长江!O29 | AB29: =萍钢!J29 | AC29: =萍钢!K29 | AD29: =金虹!H29 | AE29: =金虹!I29 | AF29: =南钢!H29 | AG29: =南钢!I29 | AH29: =鄂钢!H29 | AI29: =鄂钢!I29 | AJ29: =贵航!H29 | AK29: =贵航!I29 | AL29: =萍钢!H29 | AM29: =萍钢!I29 | AN29: =桂鑫!H29 | AO29: =桂鑫!I29 | AP29: =金安!G29 | AQ29: =金安!H29 | AR29: =马钢!H29 | AS29: =马钢!I29 | AT29: =中天!H29 | AU29: =中天!I29 | AV29: 80 | AW29: 3360 | AX29: =新兴铸管!H29 | AY29: =新兴铸管!I29 | AZ29: =新兴铸管!J29 | BA29: =新兴铸管!K29 | BP29: =马钢!T29 | BQ29: =马钢!U29 | BR29: 170 | BS29: -140 | BT29: 80 | BU29: 3360 | BV29: 120 | BW29: -40 | BX29: 290 | BY29: -210 | BZ29: 220 | CA29: -150 | CB29: 0 | CC29: 70
B30: 28 | C30: 9 | D30: HRB400E | F30: =E30*G30 | P30: =徐钢!H30 | Q30: =徐钢!I30 | R30: =闽源!H30 | S30: =闽源!I30 | T30: =长江!H30 | U30: =长江!I30 | V30: =长江!J30 | W30: =长江!K30 | X30: =长江!L30 | Y30: =长江!M30 | Z30: =长江!N30 | AA30: =长江!O30 | AB30: =萍钢!J30 | AC30: =萍钢!K30 | AD30: =金虹!H30 | AE30: =金虹!I30 | AF30: =南钢!H30 | AG30: =南钢!I30 | AH30: =鄂钢!H30 | AI30: =鄂钢!I30 | AJ30: =贵航!H30 | AK30: =贵航!I30 | AL30: =萍钢!H30 | AM30: =萍钢!I30 | AN30: =桂鑫!H30 | AO30: =桂鑫!I30 | AP30: =金安!G30 | AQ30: =金安!H30 | AR30: =马钢!H30 | AS30: =马钢!I30 | AT30: =中天!H30 | AU30: =中天!I30 | AV30: 120 | AW30: 3380 | AX30: =新兴铸管!H30 | AY30: =新兴铸管!I30 | AZ30: =新兴铸管!J30 | BA30: =新兴铸管!K30 | BP30: =马钢!T30 | BQ30: =马钢!U30 | BR30: 200 | BS30: #VALUE! | BT30: 120 | BU30: 3380 | BV30: 180 | BW30: -60 | BX30: 320 | BY30: -200 | BZ30: 240 | CA30: #VALUE! | CB30: 80 | CC30: #VALUE!
B31: 28 | C31: 12 | D31: HRB400E | F31: =E31*G31 | P31: =徐钢!H31 | Q31: =徐钢!I31 | R31: =闽源!H31 | S31: =闽源!I31 | T31: =长江!H31 | U31: =长江!I31 | V31: =长江!J31 | W31: =长江!K31 | X31: =长江!L31 | Y31: =长江!M31 | Z31: =长江!N31 | AA31: =长江!O31 | AB31: =萍钢!J31 | AC31: =萍钢!K31 | AD31: =金虹!H31 | AE31: =金虹!I31 | AF31: =南钢!H31 | AG31: =南钢!I31 | AH31: =鄂钢!H31 | AI31: =鄂钢!I31 | AJ31: =贵航!H31 | AK31: =贵航!I31 | AL31: =萍钢!H31 | AM31: =萍钢!I31 | AN31: =桂鑫!H31 | AO31: =桂鑫!I31 | AP31: =金安!G31 | AQ31: =金安!H31 | AR31: =马钢!H31 | AS31: =马钢!I31 | AT31: =中天!H31 | AU31: =中天!I31 | AV31: 120 | AW31: 3380 | AX31: =新兴铸管!H31 | AY31: =新兴铸管!I31 | AZ31: =新兴铸管!J31 | BA31: =新兴铸管!K31 | BP31: =马钢!T31 | BQ31: =马钢!U31 | BR31: 200 | BS31: #VALUE! | BT31: 120 | BU31: 3380 | BV31: 180 | BW31: -60 | BX31: 390 | BY31: -270 | BZ31: 240 | CA31: #VALUE! | CB31: 80 | CC31: #VALUE!
B32: 32 | C32: 9 | D32: HRB400E | F32: =E32*G32 | P32: =徐钢!H32 | Q32: =徐钢!I32 | R32: =闽源!H32 | S32: =闽源!I32 | T32: =长江!H32 | U32: =长江!I32 | V32: =长江!J32 | W32: =长江!K32 | X32: =长江!L32 | Y32: =长江!M32 | Z32: =长江!N32 | AA32: =长江!O32 | AB32: =萍钢!J32 | AC32: =萍钢!K32 | AD32: =金虹!H32 | AE32: =金虹!I32 | AF32: =南钢!H32 | AG32: =南钢!I32 | AH32: =鄂钢!H32 | AI32: =鄂钢!I32 | AJ32: =贵航!H32 | AK32: =贵航!I32 | AL32: =萍钢!H32 | AM32: =萍钢!I32 | AN32: =桂鑫!H32 | AO32: =桂鑫!I32 | AP32: =金安!G32 | AQ32: =金安!H32 | AR32: =马钢!H32 | AS32: =马钢!I32 | AT32: =中天!H32 | AU32: =中天!I32 | AV32: 120 | AW32: 3380 | AX32: =新兴铸管!H32 | AY32: =新兴铸管!I32 | AZ32: =新兴铸管!J32 | BA32: =新兴铸管!K32 | BP32: =马钢!T32 | BQ32: =马钢!U32 | BR32: 200 | BS32: #VALUE! | BT32: 120 | BU32: 3380 | BV32: 180 | BW32: -60 | BX32: 370 | BY32: -250 | BZ32: 240 | CA32: #VALUE! | CB32: 80 | CC32: #VALUE!
B33: 32 | C33: 12 | D33: HRB400E | F33: =E33*G33 | P33: =徐钢!H33 | Q33: =徐钢!I33 | R33: =闽源!H33 | S33: =闽源!I33 | T33: =长江!H33 | U33: =长江!I33 | V33: =长江!J33 | W33: =长江!K33 | X33: =长江!L33 | Y33: =长江!M33 | Z33: =长江!N33 | AA33: =长江!O33 | AB33: =萍钢!J33 | AC33: =萍钢!K33 | AD33: =金虹!H33 | AE33: =金虹!I33 | AF33: =南钢!H33 | AG33: =南钢!I33 | AH33: =鄂钢!H33 | AI33: =鄂钢!I33 | AJ33: =贵航!H33 | AK33: =贵航!I33 | AL33: =萍钢!H33 | AM33: =萍钢!I33 | AN33: =桂鑫!H33 | AO33: =桂鑫!I33 | AP33: =金安!G33 | AQ33: =金安!H33 | AR33: =马钢!H33 | AS33: =马钢!I33 | AT33: =中天!H33 | AU33: =中天!I33 | AV33: 120 | AW33: 3380 | AX33: =新兴铸管!H33 | AY33: =新兴铸管!I33 | AZ33: =新兴铸管!J33 | BA33: =新兴铸管!K33 | BP33: =马钢!T33 | BQ33: =马钢!U33 | BR33: 200 | BS33: #VALUE! | BT33: 120 | BU33: 3380 | BV33: 180 | BW33: -60 | BX33: 440 | BY33: -320 | BZ33: 240 | CA33: #VALUE! | CB33: 50 | CC33: #VALUE!
A34: 合计（吨） | E34: =SUM(E9:E33) | F34: =SUM(F9:F33) | G34: =F34/E34 | H34: =SUM(H9:H33) | I34: =SUM(I9:I33) | J34: =SUM(J9:J33) | K34: =SUM(K9:K33) | L34: =SUM(L9:L33) | M34: =SUM(M9:M33) | N34: =SUM(N9:N33) | O34: 下浮 | T34: =长江!H34 | U34: =长江!I34 | AL34: =萍钢!L34 | AM34: =萍钢!M34 | AP34: =金安!G34 | AQ34: =金安!H34 | AR34: 代理商 | AS34: 工程户 | BP34: 代理商 | BQ34: 工程户 | BV34: 0 | BW34: 0
G35: 平均网差 | H35: =SUM(H34:M34) | O35: 备注 | AL35: =萍钢!L35 | AM35: =萍钢!M35 | BV35: 0 | BW35: 0
T39: =#REF!-#REF! | AR39: 3520 | AS39: 3380 | BP39: 3520 | BQ39: 3380
T41: =#REF!-#REF! | AR41: 3380 | AS41: 3210 | BP41: 3380 | BQ41: 3210

Sheet 徐钢
F1: 其他 | G1: 网价[2026-04-29] | H1: 1 | J1: 1
A2: 钢材询价表（徐钢） | F2: 高线10基价
F3: 盘螺10基价 | G3: 3540 | H3: 3360
A4: 需求单位： | F4: 螺纹18基价 | G4: 3360 | H4: 3190
F5: 不开票运费
F6: 一票制运费 | H6: 0 | I6: / | J6: 0 | K6: / | L6: 0
F7: 附加运费 | H7: 0 | I7: / | J7: 0 | K7: /
A8: 等级 | B8: 规格 | C8: 长度（米） | D8: 材质 | E8: 数量（吨） | G8: 合肥市场网价 | H8: 闽曜 | I8: 网差 | J8: 闽曜 | K8: 网差 | L8: 极差 | M8: 件重 | N8: 件重
A9: 一级钢 | B9: 6 | D9: HPB300 | E9: =报价表!E9
B10: 8 | D10: HPB300 | E10: =报价表!E10
B11: 10 | D11: HPB300 | E11: =报价表!E11
A12: 抗震 三级钢 | B12: 6 | D12: HRB400E | E12: =报价表!E12 | G12: =G3+300+G6 | H12: =H3+H6+H7+300 | I12: =G12-H12 | J12: =J3+J6+J7+300 | K12: =G12-J12 | L12: =L3+L6+L7+300
B13: 8 | D13: HRB400E | E13: =报价表!E13 | G13: =G3+G6+G7 | H13: =H3+H6+H7 | I13: =G13-H13 | J13: =J3+J6+J7 | K13: =G13-J13 | L13: =L3+L6+L7
B14: 10 | D14: HRB400E | E14: =报价表!E14 | G14: =G3+G6+G7 | H14: =H3+H6+H7 | I14: =G14-H14 | J14: =J3+J6+J7 | K14: =G14-J14 | L14: =L3+L6+L7
B15: 12 | D15: HRB400E | E15: =报价表!E15 | H15: =H3+H6+50 | J15: =J3+J6+50 | L15: 50
B16: 12 | C16: 9 | D16: HRB400E | E16: =报价表!E16 | G16: =G4+G6+G7+100 | H16: =H4+60+H6+H7-10 | I16: =G16-H16 | J16: =J4+60+J6+J7 | K16: =G16-J16 | L16: 50 | M16: 1.998 | N16: 1.998
B17: 12 | C17: 12 | D17: HRB400E | E17: =报价表!E17 | G17: =G4+G6+G7+100 | H17: =H4+H6+60+H7-10 | I17: =G17-H17 | J17: =J4+J6+60+J7 | K17: =G17-J17 | L17: 50 | M17: 2.131 | N17: 2.664
B18: 14 | C18: 9 | D18: HRB400E | E18: =报价表!E18 | G18: =G4+G6+G7+50 | H18: =H4+H6+H7+50 | I18: =G18-H18 | J18: =J4+J6+J7+50 | K18: =G18-J18 | L18: 50 | M18: 1.96 | N18: 1.96
B19: 14 | C19: 12 | D19: HRB400E | E19: =报价表!E19 | G19: =G4+G6+G7+50 | H19: =H4+H6+H7+50 | I19: =G19-H19 | J19: =J4+J6+J7+50 | K19: =G19-J19 | L19: 50 | M19: 2.468 | N19: 2.614
B20: 16 | C20: 9 | D20: HRB400E | E20: =报价表!E20 | G20: =G4+G6+G7+30+20 | H20: =H4+H6+30+H7+10 | I20: =G20-H20 | J20: =J4+J6+30+J7 | K20: =G20-J20 | L20: 40 | M20: 1.991 | N20: 1.991
B21: 16 | C21: 12 | D21: HRB400E | E21: =报价表!E21 | G21: =G4+G6+G7+30+20 | H21: =H4+H6+30+H7+10 | I21: =G21-H21 | J21: =J4+J6+30+J7 | K21: =G21-J21 | L21: 40 | M21: 2.465 | N21: 2.654
B22: 18 | C22: 9 | D22: HRB400E | E22: =报价表!E22 | G22: =G4+G6+G7 | H22: =H4+H6+H7+30 | I22: =G22-H22 | J22: =J4+J6+J7 | K22: =G22-J22 | L22: 30 | M22: 1.98 | N22: 1.98
B23: 18 | C23: 12 | D23: HRB400E | E23: =报价表!E23 | G23: =G4+G6+G7 | H23: =H4+H6+H7+30 | I23: =G23-H23 | J23: =J4+J6+J7 | K23: =G23-J23 | L23: 30 | M23: 2.4 | N23: 2.64
B24: 20 | C24: 9 | D24: HRB400E | E24: =报价表!E24 | G24: =G4+G6+G7+30+20 | H24: =H4+H6+30+H7+10 | I24: =G24-H24 | J24: =J4+J6+30+J7 | K24: =G24-J24 | L24: 40 | M24: 2.001 | N24: 2.001
B25: 20 | C25: 12 | D25: HRB400E | E25: =报价表!E25 | G25: =G4+G6+G7+30+20 | H25: =H4+H6+30+H7+10 | I25: =G25-H25 | J25: =J4+J6+30+J7 | K25: =G25-J25 | L25: 40 | M25: 2.3712 | N25: 2.668
B26: 22 | C26: 9 | D26: HRB400E | E26: =报价表!E26 | G26: =G4+G6+G7+30+20+30 | H26: =H4+H6+40+H7 | I26: =G26-H26 | J26: =J4+J6+30+J7 | K26: =G26-J26 | L26: 40 | M26: 2.146 | N26: 2.012
B27: 22 | C27: 12 | D27: HRB400E | E27: =报价表!E27 | G27: =G4+G6+G7+30+20+30 | H27: =H4+H6+30+H7+10 | I27: =G27-H27 | J27: =J4+J6+30+J7 | K27: =G27-J27 | L27: 40 | M27: 2.503 | N27: 2.682
B28: 25 | C28: 9 | D28: HRB400E | E28: =报价表!E28 | G28: =G4+G6+G7+50+30 | H28: =H4+H6+50+H7 | I28: =G28-H28 | J28: =J4+J6+50+J7 | K28: =G28-J28 | L28: =L4+L6+50+L7 | M28: 2.426 | N28: 1.906
B29: 25 | C29: 12 | D29: HRB400E | E29: =报价表!E29 | G29: =G4+G6+G7+50+30 | H29: =H4+H6+50+H7 | I29: =G29-H29 | J29: =J4+J6+50+J7 | K29: =G29-J29 | L29: =L4+L6+50+L7 | M29: 2.772 | N29: 2.541
B30: 28 | C30: 9 | D30: HRB400E | E30: =报价表!E30 | G30: =G4+G6+100+G7 | H30: =H4+H6+100+H7 | I30: =G30-H30 | J30: =J4+J6+100+J7 | K30: =G30-J30 | L30: =L4+L6+100+L7 | M30: 2.174 | N30: 1.956
B31: 28 | C31: 12 | D31: HRB400E | E31: =报价表!E31 | G31: =G4+G6+100+G7 | H31: =H4+H6+100+H7 | I31: =G31-H31 | J31: =J4+J6+100+J7 | K31: =G31-J31 | L31: =L4+L6+100+L7 | M31: 2.318 | N31: 2.608
B32: 32 | C32: 9 | D32: HRB400E | E32: =报价表!E32 | G32: =G4+G6+100+G7 | H32: =H4+H6+100+H7 | I32: =G32-H32 | J32: =J4+J6+100+J7 | K32: =G32-J32 | L32: =L4+L6+100+L7 | M32: 2.272 | N32: 1.988
B33: 32 | C33: 12 | D33: HRB400E | E33: =报价表!E33 | G33: =G4+G6+100+G7 | H33: =H4+H6+100+H7 | I33: =G33-H33 | J33: =J4+J6+100+J7 | K33: =G33-J33 | L33: =L4+L6+100+L7 | M33: 2.272 | N33: 2.65
A34: 合计（吨） | E34: =SUM(E9:E33) | F34: 运费报价单位
F35: 不开票运费

Sheet 金虹
F1: 其他 | G1: 网价[2026-04-29] | H1: 1 | J1: /
A2: 钢材询价表（金虹） | F2: 高线10基价 | I2: /
F3: 盘螺10基价 | G3: 3530 | H3: 3335
A4: 需求单位： | F4: 螺纹14基价 | G4: 3400
F5: 不开票运费 | J5: 0
F6: 一票制运费 | H6: 0
F7: 附加运费 | H7: 0
A8: 等级 | B8: 规格 | C8: 长度（米） | D8: 材质 | E8: 数量（吨） | G8: 合肥市场网价 | H8: 云禧福 | I8: 网差 | J8: 正常级差 | K8: 件重
A9: 一级钢 | B9: 6 | D9: HPB300 | E9: =报价表!E9 | G9: / | H9: / | I9: / | J9: /
B10: 8 | D10: HPB300 | E10: =报价表!E10 | G10: / | H10: / | I10: / | J10: /
B11: 10 | D11: HPB300 | E11: =报价表!E11 | G11: / | H11: / | I11: / | J11: /
A12: 抗震 三级钢 | B12: 6 | D12: HRB400E | E12: =报价表!E12 | G12: =G3+G6+200 | H12: =H3+H6+200 | I12: =G12-H12 | J12: 200
B13: 8 | D13: HRB400E | E13: =报价表!E13 | G13: =G3+G6 | H13: =H3+H6 | I13: =G13-H13 | J13: =J3+J6
B14: 10 | D14: HRB400E | E14: =报价表!E14 | G14: =G3+G6 | H14: =H3+H6 | I14: =G14-H14 | J14: =J3+J6
B15: 12 | D15: HRB400E | E15: =报价表!E15 | G15: /
B16: 12 | C16: 9 | D16: HRB400E | E16: =报价表!E16 | G16: =G4+G6+60 | H16: =H4+H6+60 | I16: =G16-H16 | J16: 60 | K16: 1.998
B17: 12 | C17: 12 | D17: HRB400E | E17: =报价表!E17 | G17: =G4+G6+60 | H17: =H4+H6+60 | I17: =G17-H17
B18: 14 | C18: 9 | D18: HRB400E | E18: =报价表!E18 | G18: =G4+G6 | H18: =H4+H6 | I18: =G18-H18 | J18: 0 | K18: 2.004
B19: 14 | C19: 12 | D19: HRB400E | E19: =报价表!E19 | G19: =G4+G6 | H19: =H4+H6 | I19: =G19-H19 | J19: =J4+J6
B20: 16 | C20: 9 | D20: HRB400E | E20: =报价表!E20 | G20: / | H20: =H4+H6 | I20: / | J20: 0
B21: 16 | C21: 12 | D21: HRB400E | E21: =报价表!E21 | G21: / | H21: =H4+H6 | I21: / | J21: =J4+J6
B22: 18 | C22: 9 | D22: HRB400E | E22: =报价表!E22 | G22: / | H22: / | I22: / | J22: =J4+J6
B23: 18 | C23: 12 | D23: HRB400E | E23: =报价表!E23 | G23: / | H23: / | I23: / | J23: /
B24: 20 | C24: 9 | D24: HRB400E | E24: =报价表!E24 | G24: / | H24: / | I24: / | J24: /
B25: 20 | C25: 12 | D25: HRB400E | E25: =报价表!E25 | G25: / | H25: / | I25: / | J25: /
B26: 22 | C26: 9 | D26: HRB400E | E26: =报价表!E26 | G26: / | H26: / | I26: / | J26: /
B27: 22 | C27: 12 | D27: HRB400E | E27: =报价表!E27 | G27: / | H27: / | I27: / | J27: /
B28: 25 | C28: 9 | D28: HRB400E | E28: =报价表!E28 | G28: / | H28: / | I28: / | J28: /
B29: 25 | C29: 12 | D29: HRB400E | E29: =报价表!E29 | G29: / | H29: / | I29: / | J29: /
B30: 28 | C30: 9 | D30: HRB400E | E30: =报价表!E30 | G30: / | H30: / | I30: / | J30: /
B31: 28 | C31: 12 | D31: HRB400E | E31: =报价表!E31 | G31: / | H31: / | I31: / | J31: /
B32: 32 | C32: 9 | D32: HRB400E | E32: =报价表!E32 | G32: / | H32: / | I32: / | J32: /
B33: 32 | C33: 12 | D33: HRB400E | E33: =报价表!E33 | G33: / | H33: / | I33: / | J33: /
A34: 合计（吨） | E34: =SUM(E9:E33) | F34: 备注 | J34: /

Sheet 鄂钢
F1: 其他 | G1: 网价[2026-04-29] | H1: 1
A2: 钢材询价表（鄂钢） | F2: 高线10基价 | G2: / | I2: /
F3: 盘螺10基价 | G3: 3630 | H3: 3390
A4: 需求单位： | F4: 螺纹18基价 | G4: 3390
F5: 不开票运费 | I5: /
F6: 一票制运费 | G6: 0 | I6: /
F7: 附加运费 | I7: /
A8: 等级 | B8: 规格 | C8: 长度（米） | D8: 材质 | E8: 数量（吨） | G8: 合肥市场网价 | H8: 金钢 | I8: 网差 | J8: 级差 | K8: 件重
A9: 一级钢 | B9: 6 | D9: HPB300 | E9: =报价表!E9 | G9: / | H9: / | I9: /
B10: 8 | D10: HPB300 | E10: =报价表!E10 | G10: / | H10: / | I10: /
B11: 10 | D11: HPB300 | E11: =报价表!E11 | G11: / | H11: / | I11: /
A12: 抗震 三级钢 | B12: 6 | D12: HRB400E | E12: =报价表!E12 | G12: =G3++G6+290+10 | H12: =H3+H6+300 | I12: =G12-H12 | J12: 300
B13: 8 | D13: HRB400E | E13: =报价表!E13 | G13: =G3+G6+G7 | H13: =H3+H6+H7 | I13: =G13-H13 | J13: 0
B14: 10 | D14: HRB400E | E14: =报价表!E14 | G14: =G3+G6+G7 | H14: =H3+H6+H7 | I14: =G14-H14 | J14: 0
B15: 12 | D15: HRB400E | E15: =报价表!E15
B16: 12 | C16: 9 | D16: HRB400E | E16: =报价表!E16 | G16: =G4+G6+G7+90+10 | H16: =H4+H6+H7+100 | I16: =G16-H16 | J16: 100 | K16: 2.797
B17: 12 | C17: 12 | D17: HRB400E | E17: =报价表!E17 | G17: =G4+G6+G7+90+10 | H17: =H4+H6+H7+100 | I17: =G17-H17 | J17: 100 | K17: 2.984
B18: 14 | C18: 9 | D18: HRB400E | E18: =报价表!E18 | G18: =G4+G6+G7+30+20 | H18: =H4+H6+H7+50 | I18: =G18-H18 | J18: 50 | K18: 3.158
B19: 14 | C19: 12 | D19: HRB400E | E19: =报价表!E19 | G19: =G4+G6+G7+30+20 | H19: =H4+H6+H7+50 | I19: =G19-H19 | J19: 50 | K19: 3.194
B20: 16 | C20: 9 | D20: HRB400E | E20: =报价表!E20 | G20: =G4+G6+G7+30+20 | H20: =H4+H6+H7+30+20 | I20: =G20-H20 | J20: 30 | K20: 3.128
B21: 16 | C21: 12 | D21: HRB400E | E21: =报价表!E21 | G21: =G4+G6+G7+30+20 | H21: =H4+H6+H7+30+20 | I21: =G21-H21 | J21: 30 | K21: 3.223
B22: 18 | C22: 9 | D22: HRB400E | E22: =报价表!E22 | G22: =G4+G6+G7 | H22: =H4+H6+H7+20 | I22: =G22-H22 | J22: 0 | K22: 3.24
B23: 18 | C23: 12 | D23: HRB400E | E23: =报价表!E23 | G23: =G4+G6+G7 | H23: =H4+H6+H7+20 | I23: =G23-H23 | J23: 0 | K23: 3.12
B24: 20 | C24: 9 | D24: HRB400E | E24: =报价表!E24 | G24: =G4+G6+G7+50 | H24: =H4+H6+H7+50 | I24: =G24-H24 | J24: 50 | K24: 3.112
B25: 20 | C25: 12 | D25: HRB400E | E25: =报价表!E25 | G25: =G4+G6+G7+50 | H25: =H4+H6+H7+50 | I25: =G25-H25 | J25: 50 | K25: 3.26
B26: 22 | C26: 9 | D26: HRB400E | E26: =报价表!E26 | G26: =G4+G6+G7+50+30 | H26: =H4+H6+H7+50+30 | I26: =G26-H26 | J26: 80 | K26: 3.218
B27: 22 | C27: 12 | D27: HRB400E | E27: =报价表!E27 | G27: =G4+G6+G7+50+30 | H27: =H4+H6+H7+50+30 | I27: =G27-H27 | J27: 80 | K27: 3.218
B28: 25 | C28: 9 | D28: HRB400E | E28: =报价表!E28 | G28: =G4+G6+G7+60+20 | H28: =H4+H6+H7+80 | I28: =G28-H28 | J28: 80 | K28: 3.119
B29: 25 | C29: 12 | D29: HRB400E | E29: =报价表!E29 | G29: =G4+G6+G7+60+20 | H29: =H4+H6+H7+80 | I29: =G29-H29 | J29: 80 | K29: 3.234
B30: 28 | C30: 9 | D30: HRB400E | E30: =报价表!E30 | G30: =G4+G6+G7+120+30 | H30: =H4+H6+H7+120+30 | I30: =G30-H30 | J30: 150 | K30: 3.26
B31: 28 | C31: 12 | D31: HRB400E | E31: =报价表!E31 | G31: =G4+G6+G7+120+30 | H31: =H4+H6+H7+120+30 | I31: =G31-H31 | J31: 150 | K31: 3.188
B32: 32 | C32: 9 | D32: HRB400E | E32: =报价表!E32 | G32: =G4+G6+G7+120+30 | H32: =H4+H6+H7+120+30 | I32: =G32-H32 | J32: 150 | K32: 3.123
B33: 32 | C33: 12 | D33: HRB400E | E33: =报价表!E33 | G33: =G4+G6+G7+120+30 | H33: =H4+H6+H7+120+30 | I33: =G33-H33 | J33: 150 | K33: 3.029
A34: 合计（吨） | E34: =SUM(E9:E33) | F34: 运费报价单位
F35: 不开票运费

Sheet 闽源
F1: 其他 | G1: 网价[2026-04-29] | H1: 1 | J1: 2
A2: 钢材询价表（ 闽源） | F2: 高线10基价
F3: 盘螺10基价 | G3: 3560 | H3: 3370
A4: 需求单位： | F4: 螺纹18基价 | G4: 3380 | H4: 3190
F5: 不开票运费 | J5: 0
F6: 一票制运费 | L6: 0
F7: 附加运费 | J7: 0
A8: 等级 | B8: 规格 | C8: 长度（米） | D8: 材质 | E8: 数量（吨） | G8: 合肥市场网价 | H8: 金钢 | I8: 网差 | J8: 徐州库 | K8: 网差 | L8: 正常级差 | M8: 件重
A9: 一级钢 | B9: 6 | D9: HPB300 | E9: =报价表!E9 | G9: / | H9: =H2+400 | I9: / | J9: =J2+400 | K9: / | L9: =L2+400
B10: 8 | D10: HPB300 | E10: =报价表!E10 | G10: / | H10: =H2 | I10: / | J10: =J2 | K10: / | L10: =L2
B11: 10 | D11: HPB300 | E11: =报价表!E11 | G11: / | H11: =H2 | I11: / | J11: =J2 | K11: / | L11: =L2
A12: 抗震 三级钢 | B12: 6 | D12: HRB400E | E12: =报价表!E12 | G12: =G3+390+G6+10 | H12: =H3+H6+H7+400 | I12: =G12-H12 | J12: =J3+J6+J7+400 | K12: =G12-J12 | L12: =L3+L6+L7+400
B13: 8 | D13: HRB400E | E13: =报价表!E13 | G13: =G3+G6+30 | H13: =H3+H6+H7 | I13: =G13-H13 | J13: =J3+J6+J7 | K13: =G13-J13 | L13: =L3+L6+L7
B14: 10 | D14: HRB400E | E14: =报价表!E14 | G14: =G3+G6 | H14: =H3+H6+H7 | I14: =G14-H14 | J14: =J3+J6+J7 | K14: =G14-J14 | L14: =L3+L6+L7
B15: 12 | D15: HRB400E | E15: =报价表!E15 | G15: /
B16: 12 | C16: 9 | D16: HRB400E | E16: =报价表!E16 | G16: =G4+G6+G7+100+50 | H16: =H4+H6+H7+150 | I16: =G16-H16 | J16: =J4+J6+J7+150 | K16: =G16-J16 | L16: =L3+L5+L6+150 | M16: 1.998
B17: 12 | C17: 12 | D17: HRB400E | E17: =报价表!E17 | G17: =G4+G6+G7+100+50 | H17: =H4+H6+H7+150 | I17: =G17-H17 | J17: =J4+J6+J7+150 | K17: =G17-J17 | L17: =L3+L5+L6+150 | M17: 2.664
B18: 14 | C18: 9 | D18: HRB400E | E18: =报价表!E18 | G18: =G4+G6+G7+50+10+20 | H18: =H4+H6+H7+80 | I18: =G18-H18 | J18: =J4+J6+J7+80 | K18: =G18-J18 | L18: =L3+L5+L6+80 | M18: 1.96
B19: 14 | C19: 12 | D19: HRB400E | E19: =报价表!E19 | G19: =G4+G6+G7+50+10+20 | H19: =H4+H6+H7+80 | I19: =G19-H19 | J19: =J4+J6+J7+80 | K19: =G19-J19 | L19: =L3+L5+L6+80 | M19: 2.614
B20: 16 | C20: 9 | D20: HRB400E | E20: =报价表!E20 | G20: =G4+G6+G7+50 | H20: =H4+H6+H7+50 | I20: =G20-H20 | J20: =J4+J6+J7+50 | K20: =G20-J20 | L20: =L3+L5+L6+50 | M20: 1.991
B21: 16 | C21: 12 | D21: HRB400E | E21: =报价表!E21 | G21: =G4+G6+G7+50 | H21: =H4+H6+H7+50 | I21: =G21-H21 | J21: =J4+J6+J7+50 | K21: =G21-J21 | L21: =L3+L5+L6+50 | M21: 2.654
B22: 18 | C22: 9 | D22: HRB400E | E22: =报价表!E22 | G22: =G4+G6+G7 | H22: =H4+H6+H7 | I22: =G22-H22 | J22: =J4+J6+J7 | K22: =G22-J22 | L22: =L3+L5+L6 | M22: 1.98
B23: 18 | C23: 12 | D23: HRB400E | E23: =报价表!E23 | G23: =G4+G6+G7 | H23: =H4+H6+H7 | I23: =G23-H23 | J23: =J4+J6+J7 | K23: =G23-J23 | L23: =L3+L5+L6 | M23: 2.64
B24: 20 | C24: 9 | D24: HRB400E | E24: =报价表!E24 | G24: =G4+G6+G7+50 | H24: =H4+H6+H7+50 | I24: =G24-H24 | J24: =J4+J6+J7+50 | K24: =G24-J24 | L24: =L3+L5+L6+50 | M24: 2.001
B25: 20 | C25: 12 | D25: HRB400E | E25: =报价表!E25 | G25: =G4+G6+G7+50 | H25: =H4+H6+H7+50 | I25: =G25-H25 | J25: =J4+J6+J7+50 | K25: =G25-J25 | L25: =L3+L5+L6+50 | M25: 2.668
B26: 22 | C26: 9 | D26: HRB400E | E26: =报价表!E26 | G26: =G4+G6+G7+50+30 | H26: =H4+H6+H7+50+30 | I26: =G26-H26 | J26: =J4+J6+J7+50+30 | K26: =G26-J26 | L26: 80 | M26: 2.011
B27: 22 | C27: 12 | D27: HRB400E | E27: =报价表!E27 | G27: =G4+G6+G7+50+30 | H27: =H4+H6+H7+50+30 | I27: =G27-H27 | J27: =J4+J6+J7+50+30 | K27: =G27-J27 | L27: 80 | M27: 2.682
B28: 25 | C28: 9 | D28: HRB400E | E28: =报价表!E28 | G28: =G4+G6+G7+70+10 | H28: =H4+H6+H7+50+30 | I28: =G28-H28 | J28: =J4+J6+J7+50+30 | K28: =G28-J28 | L28: 80 | M28: 2.079
B29: 25 | C29: 12 | D29: HRB400E | E29: =报价表!E29 | G29: =G4+G6+G7+70+10 | H29: =H4+H6+H7+50+30 | I29: =G29-H29 | J29: =J4+J6+J7+50+30 | K29: =G29-J29 | L29: 80 | M29: 2.772
B30: 28 | C30: 9 | D30: HRB400E | E30: =报价表!E30 | G30: =G4+G6+G7+150 | H30: =H4+H6+H7+120+30 | I30: =G30-H30 | J30: =J4+J6+J7+120 | K30: =G30-J30 | L30: 150 | M30: 1.956
B31: 28 | C31: 12 | D31: HRB400E | E31: =报价表!E31 | G31: =G4+G6+G7+120+30 | H31: =H4+H6+H7+120+30 | I31: =G31-H31 | J31: =J4+J6+J7+120 | K31: =G31-J31 | L31: 150 | M31: 2.608
B32: 32 | C32: 9 | D32: HRB400E | E32: =报价表!E32 | G32: =G4+G6+G7+120+30 | H32: =H4+H6+H7+120+30 | I32: =G32-H32 | J32: =J4+J6+J7+120 | K32: =G32-J32 | L32: 150 | M32: 1.988
B33: 32 | C33: 12 | D33: HRB400E | E33: =报价表!E33 | G33: =G4+G6+G7+120+30 | H33: =H4+H6+H7+120+30 | I33: =G33-H33 | J33: =J4+J6+J7+120 | K33: =G33-J33 | L33: 150 | M33: 2.65
A34: 合计（吨） | E34: =SUM(E9:E33) | F34: 备注

Sheet 贵航
F1: 其他 | G1: 网价[2026-04-29] | H1: 1
A2: 钢材询价表（贵航） | F2: 高线10基价 | G2: /
F3: 盘螺10基价 | G3: 3560
A4: 需求单位： | F4: 螺纹18基价 | G4: 3360
F5: 不开票运费
F6: 一票制运费 | G6: 0
F7: 附加运费
A8: 等级 | B8: 规格 | C8: 长度（米） | D8: 材质 | E8: 数量（吨） | G8: 合肥市场网价 | H8: 航鑫 | I8: 网差 | J8: 件重 | K8: 正常级差 | L8: 件重
A9: 一级钢 | B9: 6 | D9: HPB300 | E9: =报价表!E9 | G9: / | H9: / | I9: /
B10: 8 | D10: HPB300 | E10: =报价表!E10 | G10: / | H10: / | I10: /
B11: 10 | D11: HPB300 | E11: =报价表!E11 | G11: / | H11: / | I11: /
A12: 抗震 三级钢 | B12: 6 | D12: HRB400E | E12: =报价表!E12 | G12: =G3+240+G6-20 | H12: =H3+H6+H7+220 | I12: =G12-H12 | K12: 220
B13: 8 | D13: HRB400E | E13: =报价表!E13 | G13: =G3+G6 | H13: =H3+H6+H7 | I13: =G13-H13 | K13: =K3+K6+K7
B14: 10 | D14: HRB400E | E14: =报价表!E14 | G14: =G3+G6 | H14: =H3+H6+H7 | I14: =G14-H14 | K14: =K3+K6+K7
B15: 10 | D15: HRB400E | E15: 16 | G15: =G4+70+70 | H15: =H4+H6+120 | I15: =G15-H15 | K15: 120
B16: 12 | C16: 9 | D16: HRB400E | E16: =报价表!E16 | G16: =G4+G6+G7+70 | H16: =H4+H6+H7+50+10 | I16: =G16-H16 | J16: 1.998 | K16: 60 | L16: 1.998
B17: 12 | C17: 12 | D17: HRB400E | E17: =报价表!E17 | G17: =G4+G6+G7+70 | H17: =H4+H6+H7+50+10 | I17: =G17-H17 | J17: 2.025 | K17: 60 | L17: 2.025
B18: 14 | C18: 9 | D18: HRB400E | E18: =报价表!E18 | G18: =G4+G6+G7+50 | H18: =H4+H6+H7+40+10 | I18: =G18-H18 | J18: 1.96 | K18: =K3+K5+K6+50 | L18: 1.96
B19: 14 | C19: 12 | D19: HRB400E | E19: =报价表!E19 | G19: =G4+G6+G7+50 | H19: =H4+H6+H7+40+10 | I19: =G19-H19 | J19: 1.96 | K19: =K3+K5+K6+50 | L19: 1.96
B20: 16 | C20: 9 | D20: HRB400E | E20: =报价表!E20 | G20: =G4+G6+G7+50 | H20: =H4+H6+H7+50 | I20: =G20-H20 | J20: 1.991 | K20: =K3+K5+K6+50 | L20: 1.991
B21: 16 | C21: 12 | D21: HRB400E | E21: =报价表!E21 | G21: =G4+G6+G7+50 | H21: =H4+H6+H7+50 | I21: =G21-H21 | J21: 1.991 | K21: =K3+K5+K6+50 | L21: 1.991
B22: 18 | C22: 9 | D22: HRB400E | E22: =报价表!E22 | G22: =G4+G6+G7 | H22: / | I22: / | J22: 1.98 | L22: 1.98
B23: 18 | C23: 12 | D23: HRB400E | E23: =报价表!E23 | G23: =G4+G6+G7 | H23: / | I23: / | J23: 2.04 | L23: 2.04
B24: 20 | C24: 9 | D24: HRB400E | E24: =报价表!E24 | G24: =G4+G6+G7+50 | H24: / | I24: / | J24: 2.001 | L24: 2.001
B25: 20 | C25: 12 | D25: HRB400E | E25: =报价表!E25 | G25: =G4+G6+G7+50 | H25: / | I25: / | J25: 2.075 | L25: 2.075
B26: 22 | C26: 9 | D26: HRB400E | E26: =报价表!E26 | G26: =G4+G6+G7+50 | H26: / | I26: / | J26: 2.012 | L26: 2.012
B27: 22 | C27: 12 | D27: HRB400E | E27: =报价表!E27 | G27: =G4+G6+G7+50 | H27: / | I27: / | J27: 1.967 | L27: 1.967
B28: 25 | C28: 9 | D28: HRB400E | E28: =报价表!E28 | G28: =G4+G6+G7+50 | H28: / | I28: / | J28: 2.079 | L28: 2.079
B29: 25 | C29: 12 | D29: HRB400E | E29: =报价表!E29 | G29: =G4+G6+G7+50 | H29: / | I29: / | J29: 2.079 | L29: 2.079
B30: 28 | C30: 9 | D30: HRB400E | E30: =报价表!E30 | G30: / | H30: / | I30: / | J30: 1.956 | L30: 1.956
B31: 28 | C31: 12 | D31: HRB400E | E31: =报价表!E31 | G31: / | H31: / | I31: / | J31: 2.029 | L31: 2.029
B32: 32 | C32: 9 | D32: HRB400E | E32: =报价表!E32 | G32: / | H32: / | I32: / | J32: 1.988 | L32: 1.988
B33: 32 | C33: 12 | D33: HRB400E | E33: =报价表!E33 | G33: / | H33: / | I33: / | J33: 1.893 | L33: 1.893
A34: 合计（吨） | E34: =SUM(E9:E33)

Sheet 萍钢
F1: 其他 | G1: 网价[2026-04-29] | H1: 郑蒲港 | J1: 江西 | L1: 江西 | N1: 合肥 | P1: 南京
A2: 钢材询价表（萍钢） | F2: 高线10基价 | Q2: /
F3: 盘螺10基价 | G3: 3590 | Q3: /
A4: 需求单位： | F4: 螺纹18基价 | G4: 3360 | Q4: /
F5: 不开票运费 | K5: / | M5: / | Q5: /
F6: 一票制运费 | H6: 60 | K6: / | M6: /
F7: 附加运费 | K7: / | M7: / | Q7: /
A8: 等级 | B8: 规格 | C8: 长度（米） | D8: 材质 | E8: 数量（吨） | G8: 合肥市场网价 | H8: 嘉倍 | I8: 网差 | J8: 骞腾 | K8: 网差 | L8: 骞腾 | M8: 网差 | N8: 瑞豪 | O8: 网差 | Q8: 网差 | R8: 江西级差 | S8: 合肥级差 | T8: 江苏级差 | U8: 合肥级差 | V8: 江苏级差 | W8: 郑蒲港级差 | X8: 件重
A9: 一级钢 | B9: 6 | D9: HPB300 | E9: =报价表!E9 | G9: =G2 | H9: / | J9: / | K9: / | L9: / | M9: / | N9: / | P9: / | Q9: / | R9: / | S9: / | U9: /
B10: 8 | D10: HPB300 | E10: =报价表!E10 | G10: =G2+G6 | H10: / | J10: / | K10: / | L10: / | M10: / | N10: / | P10: / | Q10: / | R10: / | S10: / | U10: /
B11: 10 | D11: HPB300 | E11: =报价表!E11 | G11: =G2+G6 | H11: / | J11: / | K11: / | L11: / | M11: / | N11: / | P11: / | Q11: / | R11: / | S11: / | U11: /
A12: 抗震 三级钢 | B12: 6 | D12: HRB400E | E12: =报价表!E12 | G12: =G3+300+G6 | H12: =H3+H6+H7+300 | I12: =G12-H12 | J12: =J3+J6+350 | K12: =G12-J12 | L12: =L3+L6+350 | M12: =I12-L12 | N12: =N3+N6+N7+300 | O12: =G12-N12 | P12: =P3+P6+P7+300 | Q12: =G12-P12 | R12: =R3+R6+350 | S12: 310 | T12: 300 | U12: =U3+U6+U7+300 | V12: 300 | W12: 300
B13: 8 | D13: HRB400E | E13: =报价表!E13 | G13: =G3+G6+G7 | H13: =H3+H6+H7 | I13: =G13-H13 | J13: =J3+J6 | K13: =G13-J13 | L13: =L3+L6 | M13: =I13-L13 | N13: =N3+N6+N7 | O13: =G13-N13 | P13: =P3+P6+P7 | Q13: =G13-P13 | R13: =R3+R6 | S13: =S3+S6+S7 | U13: =U3+U6+U7
B14: 10 | D14: HRB400E | E14: =报价表!E14 | G14: =G3+G6+G7 | H14: =H3+H6+H7 | I14: =G14-H14 | J14: =J3+J6 | K14: =G14-J14 | L14: =L3+L6 | M14: =I14-L14 | N14: =N3+N6+N7 | O14: =G14-N14 | P14: =P3+P6+P7 | Q14: =G14-P14 | R14: =R3+R6 | S14: =S3+S6+S7 | U14: =U3+U6+U7
B15: 12 | D15: HRB400E | E15: =报价表!E15 | G15: / | M15: =I15-L15 | R15: / | S15: / | T15: / | U15: / | V15: / | W15: / | X15: /
B16: 12 | C16: 9 | D16: HRB400E | E16: =报价表!E16 | G16: =G4+G6+80+20 | H16: =H4+H6+70+30-20 | I16: =G16-H16 | J16: =J4+J6+140+60 | K16: =G16-J16 | L16: =L4+L6+140 | M16: =I16-L16 | N16: =N4+N6+70+10 | O16: =G16-N16 | P16: =P4+P6+P7+100 | Q16: =G16-P16 | R16: 200 | S16: 100 | T16: 100 | W16: 80 | X16: 2.398
B17: 12 | C17: 12 | D17: HRB400E | E17: =报价表!E17 | G17: =G4+G6+80+20 | H17: =H4+H6+70+30-20 | I17: =G17-H17 | J17: =J4+J6+140+50+60 | K17: =G17-J17 | L17: =L4+L6+140+50 | M17: =I17-L17 | N17: =N4+N6+70+10 | O17: =G17-N17 | P17: =P4+P6+P7+100 | Q17: =G17-P17 | R17: 250 | S17: 100 | T17: 100 | U17: 100 | V17: 100 | W17: 80 | X17: 2.557
B18: 14 | C18: 9 | D18: HRB400E | E18: =报价表!E18 | G18: =G4+G6+30+20 | H18: =H4+H6+30+20 | I18: =G18-H18 | J18: =J4+J6+100+40 | K18: =G18-J18 | L18: =L4+L6+100 | M18: =I18-L18 | N18: =N4+N6+30+20 | O18: =G18-N18 | P18: =P4+P6+P7+30 | Q18: =G18-P18 | R18: 140 | S18: 50 | T18: 30 | U18: 100 | V18: 100 | W18: 50 | X18: 2.396
B19: 14 | C19: 12 | D19: HRB400E | E19: =报价表!E19 | G19: =G4+G6+30+20 | H19: =H4+H6+30+20 | I19: =G19-H19 | J19: =J4+J6+100+50+40 | K19: =G19-J19 | L19: =L4+L6+100+50 | M19: =I19-L19 | N19: =N4+N6+30+20 | O19: =G19-N19 | P19: =P4+P6+P7+30 | Q19: =G19-P19 | R19: 190 | S19: 50 | T19: 30 | U19: =U4+U6+U7+40 | V19: 50 | W19: 50 | X19: 2.614
B20: 16 | C20: 9 | D20: HRB400E | E20: =报价表!E20 | G20: =G4+G6+20+10+10+10 | H20: =H4+H6+30+20 | I20: =G20-H20 | J20: =J4+J6+100+40 | K20: =G20-J20 | L20: =L4+L6+100 | M20: =I20-L20 | N20: =N4+N6+30+20 | O20: =G20-N20 | P20: =P4+P6+P7+20 | Q20: =G20-P20 | R20: 140 | S20: 30 | T20: 20 | U20: =U4+U6+U7+40 | V20: 50 | W20: 50 | X20: 2.417
B21: 16 | C21: 12 | D21: HRB400E | E21: =报价表!E21 | G21: =G4+G6+20+10+10+10 | H21: =H4+H6+30+20 | I21: =G21-H21 | J21: =J4+J6+100+50+40 | K21: =G21-J21 | L21: =L4+L6+100+50 | M21: =I21-L21 | N21: =N4+N6+30+20 | O21: =G21-N21 | P21: =P4+P6+P7+20 | Q21: =G21-P21 | R21: 190 | S21: 30 | T21: 20 | U21: =U4+U6+U7+40 | V21: 10 | W21: 50 | X21: 2.654
B22: 18 | C22: 9 | D22: HRB400E | E22: =报价表!E22 | G22: =G4+G6 | H22: =H4+H6+30 | I22: =G22-H22 | J22: =J4+J6+110+20 | K22: =G22-J22 | L22: =L4+L6+110 | M22: =I22-L22 | N22: =N4+N6+30 | O22: =G22-N22 | P22: =P4+P6+P7+10 | Q22: =G22-P22 | R22: 130 | S22: 0 | T22: 10 | U22: =U4+U6+U7+40 | V22: 10 | W22: 30 | X22: 2.52
B23: 18 | C23: 12 | D23: HRB400E | E23: =报价表!E23 | G23: =G4+G6 | H23: =H4+H6+30 | I23: =G23-H23 | J23: =J4+J6+160+20 | K23: =G23-J23 | L23: =L4+L6+160 | M23: =I23-L23 | N23: =N4+N6+30 | O23: =G23-N23 | P23: =P4+P6+P7+10 | Q23: =G23-P23 | R23: 180 | S23: 0 | T23: 10 | U23: 20 | V23: 10 | W23: 30 | X23: 2.64
B24: 20 | C24: 9 | D24: HRB400E | E24: =报价表!E24 | G24: =G22+50 | H24: =H4+H6+50 | I24: =G24-H24 | J24: =J4+J6+160+50 | K24: =G24-J24 | L24: =L4+L6+160 | M24: =I24-L24 | N24: =N4+N6+50 | O24: =G24-N24 | P24: =P6+P4+P7 | Q24: =G24-P24 | R24: 210 | S24: 50 | T24: 50 | U24: 20 | V24: 10 | W24: 50 | X24: 2.445
B25: 20 | C25: 12 | D25: HRB400E | E25: =报价表!E25 | G25: =G24 | H25: =H4+H6+50 | I25: =G25-H25 | J25: =J4+J6+140+70+50 | K25: =G25-J25 | L25: =L4+L6+140+70 | M25: =I25-L25 | N25: =N4+N6+50 | O25: =G25-N25 | P25: =P4+P6+P7 | Q25: =G25-P25 | R25: 260 | S25: 50 | T25: 50 | U25: =U6+U4+U7+50 | W25: 50 | X25: 2.668
B26: 22 | C26: 9 | D26: HRB400E | E26: =报价表!E26 | G26: =G24+30 | H26: =H4+H6+50+30 | I26: =G26-H26 | J26: =J4+J6+100+40 | K26: =G26-J26 | L26: =L4+L6+100 | M26: =I26-L26 | N26: =N4+N6+50+30 | O26: =G26-N26 | P26: =P4+P6+P7+30 | Q26: =G26-P26 | R26: 140 | S26: 80 | T26: 50 | U26: =U4+U6+U7+50 | W26: 80 | X26: 2.414
B27: 22 | C27: 12 | D27: HRB400E | E27: =报价表!E27 | G27: =G24+30 | H27: =H4+H6+50+30 | I27: =G27-H27 | J27: =J4+J6+100+50+40 | K27: =G27-J27 | L27: =L4+L6+100+50 | M27: =I27-L27 | N27: =N4+N6+50+30 | O27: =G27-N27 | P27: =P4+P6+P7+30 | Q27: =G27-P27 | R27: 190 | S27: 80 | T27: 50 | U27: =U4+U6+U7+50 | V27: 30 | W27: 80 | X27: 2.682
B28: 25 | C28: 9 | D28: HRB400E | E28: =报价表!E28 | G28: =G4+G6+G7+60+20 | H28: =H4+H6+60+20 | I28: =G28-H28 | J28: =J4+J6+120+20 | K28: =G28-J28 | L28: =L4+L6+120 | M28: =I28-L28 | N28: =N4+N6+60+20 | O28: =G28-N28 | P28: =P4+P6+P7+50 | Q28: =G28-P28 | R28: 140 | S28: 80 | T28: 50 | U28: =U4+U6+U7+50 | V28: 30 | W28: 80 | X28: 2.426
B29: 25 | C29: 12 | D29: HRB400E | E29: =报价表!E29 | G29: =G4+G6+60+20 | H29: =H4+H6+60+20 | I29: =G29-H29 | J29: =J4+J6+120+50+20 | K29: =G29-J29 | L29: =L4+L6+120+50 | M29: =I29-L29 | N29: =N4+N6+60+20 | O29: =G29-N29 | P29: =P4+P6+P7+50 | Q29: =G29-P29 | R29: 190 | S29: 80 | T29: 50 | U29: =U4+U6+U7+50 | V29: 50 | W29: 80 | X29: 2.772
B30: 28 | C30: 9 | D30: HRB400E | E30: =报价表!E30 | G30: =G4+G6+120+30 | H30: =H4+H6+120+30 | I30: =G30-H30 | J30: =J4+J6+200+10 | K30: =G30-J30 | L30: =L4+L6+200 | M30: =I30-L30 | N30: =N4+N6+120+30 | O30: =G30-N30 | P30: =P4+P6+P7+80 | Q30: =G30-P30 | R30: 210 | S30: 150 | T30: 120 | U30: =U4+U6+U7+50 | V30: 50 | W30: 150 | X30: 2.391
B31: 28 | C31: 12 | D31: HRB400E | E31: =报价表!E31 | G31: =G4+G6+120+30 | H31: =H4+H6+120+30 | I31: =G31-H31 | J31: =J4+J6+200+50+10 | K31: =G31-J31 | L31: =L4+L6+200+50 | M31: =I31-L31 | N31: =N4+N6+120+30 | O31: =G31-N31 | P31: =P4+P6+P7+80 | Q31: =G31-P31 | R31: 260 | S31: 150 | T31: 120 | U31: =U4+U6+U7+120 | V31: 80 | W31: 150 | X31: 2.608
B32: 32 | C32: 9 | D32: HRB400E | E32: =报价表!E32 | G32: =G4+G6+120+30 | H32: =H4+H6+120+30 | I32: =G32-H32 | J32: =J4+J6+250 | K32: =G32-J32 | L32: =L4+L6+250 | M32: =I32-L32 | N32: =N4+N6+120+30 | O32: =G32-N32 | P32: =P4+P6+P7+80 | Q32: =G32-P32 | R32: 260 | S32: 150 | T32: 120 | U32: =U4+U6+U7+120 | V32: 80 | W32: 150 | X32: 2.556
B33: 32 | C33: 12 | D33: HRB400E | E33: =报价表!E33 | G33: =G4+G6+120+30 | H33: =H4+H6+120+30 | I33: =G33-H33 | J33: =J4+J6+300 | K33: =G33-J33 | L33: =L4+L6+300 | M33: =I33-L33 | N33: =N4+N6+120+30 | O33: =G33-N33 | P33: =P4+P6+P7+80 | Q33: =G33-P33 | R33: 310 | S33: 150 | T33: 120 | U33: =U4+U6+U7+120 | V33: 80 | W33: 150 | X33: 2.65
A34: 合计（吨） | E34: =SUM(E9:E33) | F34: 运费报价单位
F35: 不开票运费

Sheet 金安
F1: 其他 | G1: 网价[2026-04-29] | H1: 1
A2: 钢材询价表（金安） | F2: 高线10基价 | I2: /
F3: 盘螺10基价 | I3: /
A4: 需求单位： | F4: 螺纹18基价 | G4: 3360 | I4: /
F5: 不开票运费 | I5: /
F6: 一票制运费 | G6: 0 | I6: /
F7: 附加运费 | I7: /
A8: 等级 | B8: 规格 | C8: 长度（米） | D8: 材质 | E8: 数量（吨） | G8: 合肥市场网价 | I8: 网差 | J8: 级差 | K8: 件重
A9: 一级钢 | B9: 6 | D9: HPB300 | E9: =报价表!E9 | I9: =G9-H9
B10: 8 | D10: HPB300 | E10: =报价表!E10 | I10: =G10-H10
B11: 10 | D11: HPB300 | E11: =报价表!E11 | I11: =G11-H11
A12: 抗震 三级钢 | B12: 6 | D12: HRB400E | E12: =报价表!E12 | I12: =G12-H12
B13: 8 | D13: HRB400E | E13: =报价表!E13 | I13: =G13-H13
B14: 10 | D14: HRB400E | E14: =报价表!E14 | I14: =G14-H14
B15: 12 | D15: HRB400E | E15: =报价表!E15 | I15: =G15-H15
B16: 12 | C16: 9 | D16: HRB400E | E16: =报价表!E16 | G16: =G4+G6+G7+140 | H16: =H4+H6+100 | I16: =G16-H16 | J16: 100 | K16: 1.998
B17: 12 | C17: 12 | D17: HRB400E | E17: =报价表!E17 | G17: =G4+G6+G7+140 | H17: =H4+H6+100 | I17: =G17-H17 | J17: 100 | K17: 2.025
B18: 14 | C18: 9 | D18: HRB400E | E18: =报价表!E18 | G18: =G4+G6+G7+60 | H18: =H4+H6+50 | I18: =G18-H18 | J18: 50 | K18: 1.96
B19: 14 | C19: 12 | D19: HRB400E | E19: =报价表!E19 | G19: =G4+G6+G7+60 | H19: =H4+H6+50 | I19: =G19-H19 | J19: 50 | K19: 1.96
B20: 16 | C20: 9 | D20: HRB400E | E20: =报价表!E20 | G20: =G4+G6+G7+50 | H20: =H4+H6+40 | I20: =G20-H20 | J20: 40 | K20: 1.991
B21: 16 | C21: 12 | D21: HRB400E | E21: =报价表!E21 | G21: =G4+G6+G7+50 | H21: =H4+H6+40 | I21: =G21-H21 | J21: 40 | K21: 1.991
B22: 18 | C22: 9 | D22: HRB400E | E22: =报价表!E22 | G22: =G4+G6+G7 | H22: =H4+H6+30 | I22: =G22-H22 | J22: 30 | K22: 1.98
B23: 18 | C23: 12 | D23: HRB400E | E23: =报价表!E23 | G23: =G4+G6+G7 | H23: =H4+H6+30 | I23: =G23-H23 | J23: 30 | K23: 2.04
B24: 20 | C24: 9 | D24: HRB400E | E24: =报价表!E24 | G24: =G4+G6+G7+50 | H24: =H4+H6+30 | I24: =G24-H24 | J24: 30 | K24: 2.001
B25: 20 | C25: 12 | D25: HRB400E | E25: =报价表!E25 | G25: =G4+G6+G7+50 | H25: =H4+H6+30 | I25: =G25-H25 | J25: 30 | K25: 2.075
B26: 22 | C26: 9 | D26: HRB400E | E26: =报价表!E26 | G26: =G4+G6+G7+50 | H26: =H4+H6+50 | I26: =G26-H26 | J26: 50 | K26: 1.985
B27: 22 | C27: 12 | D27: HRB400E | E27: =报价表!E27 | G27: =G4+G6+G7+50 | H27: =H4+H6+50 | I27: =G27-H27 | J27: 50 | K27: 1.967
B28: 25 | C28: 9 | D28: HRB400E | E28: =报价表!E28 | G28: =G4+G6+G7+80 | H28: =H4+H6+90 | I28: =G28-H28 | J28: 90 | K28: 1.975
B29: 25 | C29: 12 | D29: HRB400E | E29: =报价表!E29 | G29: =G4+G6+G7+80 | H29: =H4+H6+90 | I29: =G29-H29 | J29: 90 | K29: 2.079
B30: 28 | C30: 9 | D30: HRB400E | E30: =报价表!E30 | I30: =G30-H30
B31: 28 | C31: 12 | D31: HRB400E | E31: =报价表!E31 | I31: =G31-H31
B32: 32 | C32: 9 | D32: HRB400E | E32: =报价表!E32 | I32: =G32-H32
B33: 32 | C33: 12 | D33: HRB400E | E33: =报价表!E33 | I33: =G33-H33
A34: 合计（吨） | E34: =SUM(E9:E33) | F34: 备注

Sheet 长江
F1: 其他 | G1: 网价[2026-04-29] | H1: 铁山/金强 | J1: 方圆/乐福祥 | L1: 宏远/乐福祥 | N1: 铁山/顺朝 | P1: 铁山/顺朝 | R1: 通配/钢晨 | T1: 南京库 | V1: 安徽级差 | W1: 江苏级差
A2: 钢材询价表（长江） | F2: 高线10基价 | I2: / | K2: / | M2: / | O2: / | Q2: / | S2: / | U2: /
F3: 盘螺10基价 | G3: 3640 | J3: 3430
A4: 需求单位：五河县兴五新型建材有限公司 | F4: 螺纹18基价 | G4: 3400 | J4: 3170
F5: 不开票运费 | K5: / | M5: / | O5: / | Q5: / | S5: / | U5: /
F6: 一票制运费 | J6: 15
F7: 附加运费 | I7: / | K7: / | M7: / | O7: / | S7: / | U7: /
A8: 等级 | B8: 规格 | C8: 长度（米） | D8: 材质 | E8: 数量（吨） | G8: 合肥市场网价 | H8: 钢厂 | I8: 网差 | J8: 蚌埠库 | K8: 网差 | L8: 阜阳库 | M8: 网差 | N8: 合肥港 | O8: 网差 | P8: 合肥铁四局 | Q8: 网差 | R8: 安庆库 | S8: 网差 | T8: 南京库 | U8: 网差 | V8: 极差 | W8: 极差 | X8: 件重
A9: 一级钢 | B9: 6 | D9: HPB300 | E9: =报价表!E9 | G9: =G2+G6 | H9: =H2+H6 | I9: 0 | J9: =J2+J6 | K9: =G9-J9 | L9: =L2+L6 | M9: =G9-L9 | N9: =N2+N6 | O9: =G9-N9 | P9: =P2+P6 | Q9: =G9-P9 | R9: =R2+R6 | S9: =G9-R9 | T9: =T2+T6 | U9: =G9-T9
B10: 8 | D10: HPB300 | E10: =报价表!E10 | G10: =G2+G6 | H10: =H2+H6 | I10: =G10-H10 | J10: =J2+J6 | K10: =G10-J10 | L10: =L2+L6 | M10: =G10-L10 | N10: =N2+N6 | O10: =G10-N10 | P10: =P2+P6 | Q10: =G10-P10 | R10: =R2+R6 | S10: =G10-R10 | T10: =T2+T6 | U10: =G10-T10
B11: 10 | D11: HPB300 | E11: =报价表!E11 | G11: =G2+G6 | H11: =H2+H6 | I11: =G11-H11 | J11: =J2+J6 | K11: =G11-J11 | L11: =L2+L6 | M11: =G11-L11 | N11: =N2+N6 | O11: =G11-N11 | P11: =P2+P6 | Q11: =G11-P11 | R11: =R2+R6 | S11: =G11-R11 | T11: =T2+T6 | U11: =G11-T11
A12: 抗震 三级钢 | B12: 6 | D12: HRB400E | E12: =报价表!E12 | G12: =G3+300+G6 | H12: =H3+300+H6 | I12: =G12-H12 | J12: =J3+300+J6 | K12: =G12-J12 | L12: =L3+300+L6 | M12: =G12-L12 | N12: =N3+300+N6 | O12: =G12-N12 | P12: =P3+300+P6 | Q12: =G12-P12 | R12: =R3+300+R6 | S12: =G12-R12 | T12: =T3+300+T6 | U12: =G12-T12 | V12: 300 | W12: 300
B13: 8 | D13: HRB400E | E13: =报价表!E13 | G13: =G3+G6+G7 | H13: =H3+H6+H7 | I13: =G13-H13 | J13: =J3+J6+J7 | K13: =G13-J13 | L13: =L3+L6+L7 | M13: =G13-L13 | N13: =N3+N6+N7 | O13: =G13-N13 | P13: =P3+P6+P7 | Q13: =G13-P13 | R13: =R3+R6+R7 | S13: =G13-R13 | T13: =T3+T6+T7 | U13: =G13-T13 | V13: 0 | W13: 0
B14: 10 | D14: HRB400E | E14: =报价表!E14 | G14: =G3+G6+G7 | H14: =H3+H6+H7 | I14: =G14-H14 | J14: =J3+J6+J7 | K14: =G14-J14 | L14: =L3+L6+L7 | M14: =G14-L14 | N14: =N3+N6+N7 | O14: =G14-N14 | P14: =P3+P6+P7 | Q14: =G14-P14 | R14: =R3+R6+R7 | S14: =G14-R14 | T14: =T3+T6+T7 | U14: =G14-T14 | V14: 0 | W14: 0
B15: 12 | D15: HRB400E | E15: =报价表!E15 | G15: =G14 | I15: =G15-H15
B16: 12 | C16: 9 | D16: HRB400E | E16: =报价表!E16 | G16: =G4+G6+G7+100 | H16: =H4+H6+H7+80+20 | I16: =G16-H16 | J16: =J4+J6+J7+80+20 | K16: =G16-J16 | L16: =L4+L6+L7+80 | M16: =G16-L16 | N16: =N4+N6+N7+80 | O16: =G16-N16 | P16: =P4+P6+P7+80 | Q16: =G16-P16 | R16: =R4+R6+R7+80 | S16: =G16-R16 | T16: =T4+T6+T7+100 | U16: =G16-T16 | V16: 100 | W16: 100 | X16: 1.998
B17: 12 | C17: 12 | D17: HRB400E | E17: =报价表!E17 | G17: =G4+G6+G7+100 | H17: =H4+H6+H7+80+20 | I17: =G17-H17 | J17: =J4+J6+J7+80+20 | K17: =G17-J17 | L17: =L4+L6+L7+80 | M17: =G17-L17 | N17: =N4+N6+N7+80 | O17: =G17-N17 | P17: =P4+P6+P7+80 | Q17: =G17-P17 | R17: =R4+R6+R7+80 | S17: =G17-R17 | T17: =T4+T6+T7+100 | U17: =G17-T17 | V17: 100 | W17: 100 | X17: 2.003
B18: 14 | C18: 9 | D18: HRB400E | E18: =报价表!E18 | G18: =G4+G6+G7+30+20 | H18: =H4+H6+H7+30+20 | I18: =G18-H18 | J18: =J4+J6+J7+30+20 | K18: =G18-J18 | L18: =L4+L6+L7+30 | M18: =G18-L18 | N18: =N4+N6+N7+30 | O18: =G18-N18 | P18: =P4+P6+P7+30 | Q18: =G18-P18 | R18: =R4+R6+R7+30 | S18: =G18-R18 | T18: =T4+T6+T7+30 | U18: =G18-T18 | V18: 50 | W18: 30 | X18: 1.993
B19: 14 | C19: 12 | D19: HRB400E | E19: =报价表!E19 | G19: =G4+G6+G7+30+20 | H19: =H4+H6+H7+30+20 | I19: =G19-H19 | J19: =J4+J6+J7+30+20 | K19: =G19-J19 | L19: =L4+L6+L7+30 | M19: =G19-L19 | N19: =N4+N6+N7+30 | O19: =G19-N19 | P19: =P4+P6+P7+30 | Q19: =G19-P19 | R19: =R4+R6+R7+30 | S19: =G19-R19 | T19: =T4+T6+T7+30 | U19: =G19-T19 | V19: 50 | W19: 30 | X19: 2.004
B20: 16 | C20: 9 | D20: HRB400E | E20: =报价表!E20 | G20: =G4+G6+G7+30+10+10 | H20: =H4+H6+H7+30+20 | I20: =G20-H20 | J20: =J4+J6+J7+30+20 | K20: =G20-J20 | L20: =L4+L6+L7+20 | M20: =G20-L20 | N20: =N4+N6+N7+20 | O20: =G20-N20 | P20: =P4+P6+P7+20 | Q20: =G20-P20 | R20: =R4+R6+R7+20+10 | S20: =G20-R20 | T20: =T4+T6+T7 | U20: =G20-T20 | V20: 50 | W20: 0 | X20: 1.991
B21: 16 | C21: 12 | D21: HRB400E | E21: =报价表!E21 | G21: =G4+G6+G7+30+10+10 | H21: =H4+H6+H7+30+20 | I21: =G21-H21 | J21: =J4+J6+J7+30+20 | K21: =G21-J21 | L21: =L4+L6+L7+20 | M21: =G21-L21 | N21: =N4+N6+N7+20 | O21: =G21-N21 | P21: =P4+P6+P7+20 | Q21: =G21-P21 | R21: =R4+R6+R7+20+10 | S21: =G21-R21 | T21: =T4+T6+T7 | U21: =G21-T21 | V21: 50 | W21: 0 | X21: 1.991
B22: 18 | C22: 9 | D22: HRB400E | E22: =报价表!E22 | G22: =G4+G6+G7 | H22: =H4+H6+H7 | I22: =G22-H22 | J22: =J4+J6+J7 | K22: =G22-J22 | L22: =L4+L6+L7 | M22: =G22-L22 | N22: =N4+N6+N7 | O22: =G22-N22 | P22: =P4+P6+P7 | Q22: =G22-P22 | R22: =R4+R6+R7 | S22: =G22-R22 | T22: =T4+T6+T7 | U22: =G22-T22 | V22: 0 | W22: 0 | X22: 1.998
B23: 18 | C23: 12 | D23: HRB400E | E23: =报价表!E23 | G23: =G4+G6+G7 | H23: =H4+H6+H7 | I23: =G23-H23 | J23: =J4+J6+J7 | K23: =G23-J23 | L23: =L4+L6+L7 | M23: =G23-L23 | N23: =N4+N6+N7 | O23: =G23-N23 | P23: =P4+P6+P7 | Q23: =G23-P23 | R23: =R4+R6+R7 | S23: =G23-R23 | T23: =T4+T6+T7 | U23: =G23-T23 | V23: 0 | W23: 0 | X23: 1.992
